Workbook
Name Slicer_Bill_To: #N/A
Name Slicer_Description: #N/A

Sheet Summary
A1: Purchase
A2: Row Labels | B2: Sum of Ginger Kgs | C2: Sum of Garlic Kgs
A3: 45689 | B3: 130 | C3: 364
A4: 45717 | B4: 921 | C4: 1004
A5: 45748 | B5: 295 | C5: 419
A6: 45778 | B6: 593 | C6: 829
A7: 45809 | B7: 350 | C7: 1381
A8: 45839 | B8: 514.9 | C8: 329
A9: 45870 | B9: 575 | C9: 889
A10: 45901 | B10: 640 | C10: 1154
A11: Grand Total | B11: 4018.9 | C11: 6369
A23: Sales & Expences
A24: Row Labels | B24: Sum of Sales | C24: Sum of Expences
A25: 45689 | B25: 21450 | C25: 26975
A26: 45717 | B26: 188580 | C26: 162135
A27: 45748 | B27: 105060 | C27: 114833
A28: 45778 | B28: 133160 | C28: 154562
A29: 45809 | B29: 126385 | C29: 173669
A30: 45839 | B30: 164755 | C30: 89496
A31: 45870 | B31: 173370 | C31: 170293
A32: 45901 | B32: 229785 | C32: 173935
A33: Grand Total | B33: 1142545 | C33: 1065898

Sheet Raw Materials
A1: Raw Materials Procurement | B1: 2025
A2: Date | B2: Description | C2: Supplier | D2: Kgs | E2: Unit Price | F2: Transportation | G2: Price | H2: Remarks
A3: 45693 | B3: Garlic | D3: 62 | E3: 90 | G3: 5580 | H3: Rs90 per kg
A4: 45706 | B4: Ginger | D4: 40 | E4: 47.5 | F4: 200 | G4: 2100
A5: 45708 | B5: Garlic | D5: 76 | E5: 85 | F5: 560 | G5: 7020
A6: 45712 | B6: Garlic | D6: 66 | E6: 80 | F6: 520 | G6: 5800 | H6: Advance payment | K6: Date | L6: (All)
A7: 45712 | B7: Ginger | D7: 30 | G7: 1300
A8: 45714 | B8: Ginger | D8: 60 | E8: 40 | F8: 100 | G8: 2500
A9: 45716 | B9: Garlic | C9: PK Garlic Vadugapatti | D9: 160 | E9: 80 | F9: 1050 | G9: 13850 | K9: Description | L9: Sum of Kgs | M9: Sum of Price
A10: 45719 | B10: Ginger | C10: Local Purchase | D10: 20 | E10: 60 | G10: 1200 | K10: Garlic | L10: 6129 | M10: 501837.1
A11: 45720 | B11: Garlic | C11: PK Garlic Vadugapatti | D11: 98 | E11: 80 | F11: 685 | G11: 8525 | K11: Ginger | L11: 4024.9 | M11: 205884.87
A12: 45720 | B12: Ginger | C12: Bala Vegetables | D12: 56 | E12: 43 | F12: 100 | G12: 2500 | K12: Grand Total | L12: 10153.9 | M12: 707721.97
A13: 45723 | B13: Ginger | C13: Bala Vegetables | D13: 56 | E13: 43 | F13: 100 | G13: 2500
A14: 45724 | B14: Garlic | C14: PK Garlic Vadugapatti | D14: 137 | E14: 80 | F14: 810 | G14: 11770
A15: 45729 | B15: Ginger | C15: Bala Vegetables | D15: 56 | E15: 42.85 | F15: 100.4 | G15: 2500
A16: 45731 | B16: Garlic | C16: PK Garlic Vadugapatti | D16: 165 | E16: 80 | F16: 1010 | G16: 14210
A17: 45731 | B17: Ginger | C17: Jakakodi Traders | D17: 56 | E17: 38.39 | F17: 100.16 | G17: 2250 | K17: Count of Kgs | L17: Column Labels
A18: 45733 | B18: Ginger | C18: Jakakodi Traders | D18: 56 | E18: 38.39 | F18: 100.16 | G18: 2250 | K18: Row Labels | L18: Garlic | M18: Ginger | N18: Grand Total
A19: 45735 | B19: Ginger | C19: Jakakodi Traders | D19: 56 | E19: 38.39 | F19: 100.16 | G19: 2250 | K19: 45712 | L19: 1 | M19: 1 | N19: 2
A20: 45736 | B20: Ginger | C20: Jakakodi Traders | D20: 56 | E20: 38.39 | F20: 100.16 | G20: 2250 | K20: 45720 | L20: 1 | M20: 1 | N20: 2
A21: 45737 | B21: Ginger | C21: Jakakodi Traders | D21: 56 | E21: 38.39 | F21: 100.16 | G21: 2250 | K21: 45731 | L21: 1 | M21: 1 | N21: 2
A22: 45738 | B22: Ginger | C22: Ameen Bandary | D22: 5 | E22: 50 | G22: 250 | K22: 45738 | L22: 2 | M22: 1 | N22: 3
A23: 45738 | B23: Garlic | C23: Ameen Bandary | D23: 10 | E23: 75 | G23: 750 | K23: 45743 | L23: 2 | M23: 2 | N23: 4
A24: 45738 | B24: Garlic | C24: PK Garlic Vadugapatti | D24: 156 | E24: 80 | F24: 910 | G24: 13390 | K24: 45746 | L24: 1 | M24: 1 | N24: 2
A25: 45740 | B25: Ginger | C25: Jakakodi Traders | D25: 56 | E25: 38.39 | F25: 100.16 | G25: 2250 | K25: 45758 | L25: 1 | M25: 1 | N25: 2
A26: 45741 | B26: Ginger | C26: Jakakodi Traders | D26: 56 | E26: 38.39 | F26: 100.16 | G26: 2250 | K26: 45762 | L26: 2 | M26: 1 | N26: 3
A27: 45742 | B27: Ginger | C27: Jakakodi Traders | D27: 56 | E27: 38.39 | F27: 100.16 | G27: 2250 | K27: 45791 | L27: 2 | N27: 2
A28: 45743 | B28: Garlic | C28: PK Garlic Vadugapatti | D28: 160 | E28: 80 | F28: 570 | G28: =(D28*E28)+F28 -> 13370 | K28: 45807 | L28: 1 | M28: 2 | N28: 3
A29: 45743 | B29: Garlic | C29: PK Garlic Vadugapatti | D29: 120 | E29: 85 | F29: 1000 | G29: =(D29*E29)+F29 -> 11200 | K29: 45813 | L29: 2 | N29: 2
A30: 45743 | B30: Ginger | C30: Jakakodi Traders | D30: 56 | E30: 38.39 | F30: 100.16 | G30: 2250 | K30: 45830 | L30: 2 | N30: 2
A31: 45743 | B31: Ginger | C31: Jakakodi Traders | D31: 56 | E31: 38.39 | F31: 100.16 | G31: 2250 | K31: 45832 | L31: 1 | M31: 1 | N31: 2
A32: 45744 | B32: Ginger | C32: Jakakodi Traders | D32: 56 | E32: 38.39 | F32: 100.16 | G32: 2250 | K32: 45849 | L32: 1 | M32: 1 | N32: 2
A33: 45745 | B33: Ginger | C33: Jakakodi Traders | D33: 56 | E33: 38.39 | F33: 100.16 | G33: 2250 | K33: 45850 | L33: 1 | M33: 1 | N33: 2
A34: 45746 | B34: Ginger | C34: Jakakodi Traders | D34: 56 | E34: 38.39 | F34: 100.16 | G34: 2250 | K34: 45853 | L34: 1 | M34: 1 | N34: 2
A35: 45746 | B35: Garlic | C35: PK Garlic Vadugapatti | D35: 158 | E35: 80 | F35: 1020 | G35: =(D35*E35)+F35 -> 13660 | K35: 45857 | L35: 1 | M35: 1 | N35: 2
A36: 45751 | B36: Ginger | C36: Jakakodi Traders | D36: 56 | E36: 36.6 | F36: 100.4 | G36: =(D36*E36)+F36 -> 2150 | K36: 45859 | L36: 1 | M36: 1 | N36: 2
A37: 45758 | B37: Garlic | C37: Ameen Bandary | D37: 11 | E37: 80 | G37: =(D37*E37)+F37 -> 880 | K37: 45875 | L37: 1 | M37: 1 | N37: 2
A38: 45758 | B38: Ginger | C38: Ameen Bandary | D38: 15 | E38: 50 | G38: =(D38*E38)+F38 -> 750 | K38: 45877 | L38: 2 | M38: 1 | N38: 3
A39: 45759 | B39: Ginger | C39: Jakakodi Traders | D39: 56 | E39: 38.39 | F39: 100.16 | G39: 2250 | K39: 45891 | L39: 2 | N39: 2
A40: 45762 | B40: Garlic | C40: PK Garlic Vadugapatti | D40: 129 | E40: 70 | G40: =(D40*E40)+F40 -> 9030 | K40: 45900 | L40: 1 | M40: 1 | N40: 2
...

Sheet Feb 2025 - Sales
A1: Date | B1: Description | C1: Sales | D1: Expences | E1: Credit | F1: Remarks
B2: Petty Cash | C2: 42928 | F2: Hassan's Investment balance, Tobe returned. This includes Rs10550 of Garlic ruturned refund amount.
A3: 45708 | B3: KG ???? | C3: 4710
A4: 45709 | B4: 4 kg paste 2 kg peeled | C4: 1040
A5: 45710 | B5: Paste 1kg - 150 Peeled 2 kg - 230*2 = 460 Paste 130*6 = 780 Paste 130*7 = 910 | C5: 2300
A6: 45710 | B6: Tea & Cleaning Items | D6: 140
A7: 45710 | B7: Ansari sari sales balance - 770 | C7: 770
A8: 45711 | B8: 4 kg paste - 560 2 kg peeled - 480 | C8: 1040
A9: 45711 | B9: Expenses Water cane 3* 35 =105 Garlic parcel + auto fare - 520 | D9: 625
A10: 45712 | B10: Paste 2 kg - 280 (hasan) 8 kg - 1040 Peeled 2 kg - 460 Total 1780 | C10: 1780
A11: 45713 | B11: 1 kg - 150 1 kg - 130 Total - 280 only | C11: 280
A12: 45713 | B12: Tea | D12: 50
A13: 45714 | B13: Nagore dealer 19 kg *130 = 2470 Peeled 2 kg * 230 = 460 Total - 2930 | C13: 2930
A14: 45714 | B14: Tea - 50 | D14: 50
A15: 45714 | B15: Ginger 60 kg - 2400 | D15: 2400
A16: 45714 | B16: Delivery - 100 | D16: 100
A17: 45714 | B17: Head cap & cloves - 710 | D17: 710
A18: 45714 | B18: Property Rent - Jan 2025 | D18: 9000
A19: 45715 | B19: Nagore dealer 19 kg | C19: 1620 | E19: 1290 | F19: Credit to Riluwan
A20: 45715 | B20: Credit Riluwan Cleared | C20: 1290
A21: 45716 | B21: Garlic 160kg | D21: 13850
A22: 45716 | B22: 28/2/25 sales Counter sales - 150 1 kg Counter sales - 150 1 kg Counter sales - 130 500grm Rilwan ( buket )-120*6kg 720 (paste) - 130*16kg 2080 ( peeled) - 230* 2 kg 460 Total Sales - 3690 | C22: 3690
A23: 45716 | B23: Tea Exp | D23: 50
B24: Total Sales | C24: =SUM(C3:C23) -> 21450
B25: Total | C25: =SUM(C24,C2) -> 64378 | D25: =SUM(D3:D24) -> 26975
B28: Net Balance | C28: =C25-D25 -> 37403

Sheet Mar 2025 - Sales
A1: Date | B1: Invoice No | C1: Description | D1: Sales | E1: Expences | F1: Credit | G1: Remarks
A2: 45717 | C2: Opening Balance | D2: 37403
A3: 45717 | C3: Sales | D3: 7915
A4: 45717 | C4: Sales | D4: 1200
A5: 45717 | C5: Expenses | E5: 560 | G5: Pouch & Transport for Fridge
A6: 45718 | C6: Sales | D6: 7950 | J6: Row Labels | K6: Sum of Sales | L6: Sum of Expences
A7: 45718 | C7: Expenses | E7: 1110 | J7: Expenses | L7: 9940
A8: 45719 | C8: Sales | D8: 2260 | J8: Garlic Purchase | L8: 86875
A9: 45719 | C9: Ginger Purchase | E9: 1200 | G9: 20Kg * 60Rs | J9: Ginger Purchase | L9: 35950
A10: 45719 | C10: Expenses | E10: 575 | J10: Opening Balance | K10: 37403
A11: 45720 | C11: Garlic Purchase | E11: 8525 | G11: 98kg * 80Rs | J11: Petrol | L11: 600
A12: 45720 | B12: GST-023 | C12: Sales | D12: 4490 | J12: Rent | L12: 9000
A13: 45720 | C13: Expenses | E13: 100 | J13: Sales | K13: 188580
A14: 45720 | C14: Ginger Purchase | E14: 2500 | G14: 56kkgs * 43Rs | J14: Staff Salary | L14: 19220
A15: 45720 | C15: Expenses | E15: 800 | G15: 1Kg Box Purchase 100Nos | J15: Wifi Bill | L15: 550
A16: 45721 | B16: GST-023 | C16: Sales | D16: 1920 | J16: Grand Total | K16: 225983 | L16: 162135
A17: 45721 | B17: GST-024 | C17: Sales | D17: 720
A18: 45721 | C18: Expenses | E18: 140
A19: 45722 | B19: GST-025 | C19: Sales | D19: 5860
A20: 45722 | B20: GST-026 | C20: Sales | D20: 470
A21: 45722 | C21: Expenses | E21: 25
A22: 45723 | B22: GST-027 | C22: Sales | D22: 3150
A23: 45723 | C23: Ginger Purchase | E23: 2500 | G23: 56kg
A24: 45723 | C24: Expenses | E24: 1822 | G24: Thar Pai & Sealing machine
A25: 45723 | C25: Expenses | E25: 370 | G25: Tea, Petrol & Mask
A26: 45724 | C26: Garlic Purchase | E26: 11770 | G26: 137kg * 80 +810
A27: 45724 | B27: GST-028 | C27: Sales | D27: 5940
A28: 45724 | B28: GST-029 | C28: Sales | D28: 200
A29: 45724 | C29: Expenses | E29: 25
A30: 45725 | B30: GST-030 | C30: Sales | D30: 3000
A31: 45726 | B31: GST-031 | C31: Sales | D31: 6080
A32: 45726 | C32: Expenses | E32: 50
A33: 45727 | C33: Rent | E33: 9000
A34: 45727 | B34: GST-032 | C34: Sales | D34: 1080
A35: 45728 | B35: GST-033 | C35: Sales | D35: 2760
A36: 45728 | B36: GST-034 | C36: Sales | D36: 600
A37: 45728 | B37: GST-035 | C37: Sales | D37: 40
A38: 45728 | C38: Expenses | E38: 30
A39: 45729 | B39: GST-036 | C39: Sales | D39: 3730
A40: 45729 | C40: Ginger Purchase | E40: 2500 | G40: 56Kgs
...

Sheet Apr 2025 - Sales
A1: Date | B1: Invoice No | C1: Description | D1: Sales | E1: Expences | F1: Credit | G1: Remarks
A2: 45748 | C2: Opening Balance | D2: ='Mar 2025 - Sales'!D132 -> 63848
A3: 45748 | C3: March Profit Share Paid | E3: 20460
A4: 45748 | B4: INV-024 | C4: Sales | D4: 1115
A5: 45748 | C5: Expences | E5: 789
A6: 45749 | B6: INV-025 | C6: Sales | D6: 2295
A7: 45749 | C7: Expences | E7: 50
A8: 45750 | B8: INV-026 | C8: Sales | D8: 2350
A9: 45750 | B9: INV-027 | C9: Sales | D9: 3250
A10: 45750 | C10: Expences | E10: 50
A11: 45751 | C11: Ginger Purchase | E11: 2150 | I11: Row Labels | J11: Sum of Sales | K11: Sum of Expences
A12: 45751 | B12: INV-028 | C12: Sales | D12: 4260 | I12: Bills | K12: 19884
A13: 45751 | C13: Petrol | E13: 300 | I13: Expences | K13: 6384
A14: 45751 | C14: Expences | E14: 50 | I14: Garlic Purchase | K14: 32855
A15: 45752 | B15: INV-029 | C15: Sales | D15: 3795 | I15: Ginger Purchase | K15: 13650
A16: 45753 | B16: INV-030 | C16: Sales | D16: 1955 | I16: March Profit Share Paid | K16: 20460
A17: 45753 | B17: INV-031 | C17: Sales | D17: 480 | I17: Opening Balance | J17: 63848
A18: 45754 | B18: INV-032 | C18: Sales | D18: 350 | I18: Others
A19: 45754 | B19: INV-033 | C19: Sales | D19: 755 | I19: Petrol | K19: 2100
A20: 45754 | C20: Expences | E20: 50 | I20: Rent | K20: 9000
A21: 45755 | B21: INV-034 | C21: Sales | D21: 2330 | I21: Sales | J21: 105060
A22: 45755 | B22: INV-035 | C22: Sales | D22: 480 | I22: Staff Salary | K22: 10500
A23: 45756 | C23: Petrol | E23: 300 | I23: (blank)
A24: 45756 | C24: Expences | E24: 280 | I24: Grand Total | J24: 168908 | K24: 114833
A25: 45757 | B25: INV-036 | C25: Sales | D25: 1325
A26: 45757 | B26: INV-037 | C26: Sales | D26: 3120
A27: 45758 | C27: Garlic Purchase | E27: 880
A28: 45758 | C28: Ginger Purchase | E28: 750
A29: 45758 | C29: Expences | E29: 397
A30: 45758 | B30: INV-038 | C30: Sales | D30: 5310
A31: 45758 | B31: INV-039 | C31: Sales | D31: 640
A32: 45759 | C32: Ginger Purchase | E32: 2150
A33: 45759 | C33: Expences | E33: 50
A34: 45759 | B34: INV-040 | C34: Sales | D34: 5020
A35: 45760 | B35: INV-041 | C35: Sales | D35: 3690
A36: 45760 | C36: Petrol | E36: 300
A37: 45761 | B37: INV-042 | C37: Sales | D37: 2610
A38: 45761 | C38: Rent | E38: 9000
A39: 45761 | C39: Expences | E39: 25
A40: 45762 | C40: Garlic Purchase | E40: 16575
...

Sheet May 2025 - Sales
A1: Date | B1: Invoice No | C1: Description | D1: Sales | E1: Expences | F1: Credit | G1: Remarks
A2: 45778 | C2: Opening Balance | D2: ='Apr 2025 - Sales'!D108 -> 54075
A3: 45778 | C3: Expences | E3: 630
A4: 45778 | C4: Ginger Purchase | E4: 1900
A5: 45778 | B5: INV-079 | C5: Sales | D5: 1440
A6: 45778 | B6: INV-080 | C6: Sales | D6: 2100
A7: 45779 | C7: Garlic Purchase | E7: 17930
A8: 45779 | B8: INV-081 | C8: Sales | D8: 2925
A9: 45779 | C9: Expences | E9: 123
A10: 45780 | B10: INV-082 | C10: Sales | D10: 1150 | I10: Row Labels | J10: Sum of Sales | K10: Sum of Expences
A11: 45780 | C11: Expences | E11: 1052 | I11: Opening Balance | J11: 54075
A12: 45781 | B12: INV-083 | C12: Sales | D12: 4570 | I12: (blank)
A13: 45781 | C13: Petrol | E13: 300 | I13: Expences | K13: 47672
A14: 45782 | C14: Expences | E14: 225 | G14: 30th April missing | I14: Ginger Purchase | K14: 22475
A15: 45782 | C15: Expences | E15: 650 | I15: Sales | J15: 133160
A16: 45782 | B16: INV-084 | C16: Sales | D16: 3525 | I16: Garlic Purchase | K16: 62595
A17: 45782 | B17: INV-085 | C17: Sales | D17: 40 | I17: Petrol | K17: 1900
A18: 45783 | C18: Rent | E18: 9000 | I18: Rent | K18: 9000
A19: 45783 | C19: Ginger Purchase | E19: 1750 | I19: Staff Salary | K19: 9250
A20: 45783 | C20: Expences | E20: 25 | I20: Bills | K20: 550
A21: 45783 | B21: INV-086 | C21: Sales | D21: 1990 | I21: Others | K21: 1120
A22: 45783 | B22: INV-087 | C22: Sales | D22: 80 | I22: Grand Total | J22: 187235 | K22: 154562
A23: 45784 | C23: Expences | E23: 2360 | G23: Barcode Purchase 2 Nos
A24: 45784 | C24: Expences | E24: 25
A25: 45784 | B25: INV-088 | C25: Sales | D25: 700
A26: 45784 | B26: INV-089 | C26: Sales | D26: 2925
A27: 45785 | C27: Petrol | E27: 300
A28: 45785 | C28: Expences | E28: 18500 | G28: Freezer purchase
A29: 45785 | C29: Expences | E29: 50
A30: 45785 | C30: Staff Salary | E30: 3000 | G30: Siva Malar Salary advance
A31: 45785 | B31: INV-090 | C31: Sales | D31: 3225
A32: 45786 | B32: INV-091 | C32: Sales | D32: 1415
A33: 45786 | B33: INV-091 | C33: Sales | D33: 450
A34: 45786 | C34: Expences | E34: 1110
A35: 45787 | C35: Ginger Purchase | E35: 1850
A36: 45787 | C36: Expences | E36: 25
A37: 45787 | B37: INV-093 | C37: Sales | D37: 8300
A38: 45788 | B38: INV-094 | C38: Sales | D38: 1920
A39: 45788 | B39: INV-095 | C39: Sales | D39: 120
A40: 45788 | C40: Expences | E40: 14200 | G40: Freezer purchase kkl
...

Sheet June 2025 - Sales
A1: Date | B1: Invoice No | C1: Description | D1: Sales | E1: Expences | F1: Credit | G1: Remarks
A2: 45809 | C2: Opening Balance | D2: ='May 2025 - Sales'!D137 -> 32673
A3: 45809 | C3: Ginger Purchase | E3: 2500
A4: 45809 | B4: INV-147 | C4: Sales | D4: 1760
A5: 45809 | B5: INV-148 | C5: Sales | D5: 2600
A6: 45809 | C6: Expences | E6: 20
A7: 45809 | C7: Staff Salary | E7: 3000 | G7: Siva Malar Advance
A8: 45810 | B8: INV-149 | C8: Sales | D8: 120
A9: 45810 | B9: INV-150 | C9: Sales | D9: 1900
A10: 45810 | C10: Expences | E10: 210
A11: 45810 | C11: Petrol | E11: 300 | I11: Row Labels | J11: Sum of Sales | K11: Sum of Expences
A12: 45811 | C12: Ginger Purchase | E12: 2400 | I12: Opening Balance | J12: 32673
A13: 45811 | B13: INV-151 | C13: Sales | D13: 40 | I13: Ginger Purchase | K13: 18600
A14: 45811 | B14: INV-152 | C14: Sales | D14: 560 | I14: Sales | J14: 126385
A15: 45811 | B15: INV-153 | C15: Sales | D15: 1400 | I15: Expences | K15: 10525
A16: 45811 | C16: Expences | E16: 75 | I16: Petrol | K16: 1600
A17: 45812 | B17: INV-154 | C17: Sales | D17: 3540 | I17: Garlic Purchase | K17: 111892
A18: 45812 | B18: INV-155 | C18: Sales | D18: 1560 | I18: Staff Salary | K18: 10200
A19: 45812 | B19: INV-156 | C19: Sales | D19: 2780 | I19: Rent | K19: 9000
A20: 45812 | C20: Expences | E20: 50 | I20: Bills | K20: 11852
A21: 45813 | C21: Garlic Purchase | E21: 34610 | G21: Nilaa WH | I21: Advance | J21: 0
A22: 45813 | C22: Staff Salary | E22: 300 | G22: Temp | I22: Grand Total | J22: 159058 | K22: 173669
A23: 45813 | C23: Expences | E23: 25
A24: 45813 | B24: INV-157 | C24: Sales | D24: 4300
A25: 45813 | B25: INV-158 | C25: Sales | D25: 1950
A26: 45813 | B26: INV-159 | C26: Sales | D26: 790
A27: 45813 | B27: INV-160 | C27: Sales | D27: 660
A28: 45814 | B28: INV-161 | C28: Sales | D28: 120
A29: 45814 | B29: INV-162 | C29: Sales | D29: 2650 | I29: Summary of Sales and Expences - June 2025
A30: 45814 | B30: INV-163 | C30: Sales | D30: 100 | I30: Row Labels | J30: Sum of Sales | K30: Sum of Expences
A31: 45814 | B31: INV-164 | C31: Sales | D31: 100 | I31: Advance | J31: 0
A32: 45814 | B32: INV-165 | C32: Sales | D32: 1280 | I32: Bills | K32: 11852
A33: 45814 | C33: Staff Salary | E33: 100 | I33: Expences | K33: 10335
A34: 45814 | C34: Expences | E34: 50 | I34: Garlic Purchase | K34: 111892
A35: 45814 | C35: Ginger Purchase | E35: 2400 | I35: Ginger Purchase | K35: 18600
A36: 45815 | B36: INV-166 | C36: Sales | D36: 1915 | I36: Opening Balance | J36: 32673
A37: 45815 | C37: Expences | E37: 50 | I37: Petrol | K37: 1600
A38: 45816 | B38: INV-167 | C38: Sales | D38: 7380 | I38: Rent | K38: 9000
A39: 45816 | B39: INV-168 | C39: Sales | D39: 2245 | I39: Sales | J39: 126385
A40: 45816 | C40: Petrol | E40: 300 | I40: Staff Salary | K40: 10200
...

Sheet July 2025 - Sales
A1: Date | B1: Invoice No | C1: Description | D1: Sales | E1: Expences | F1: Bill To | G1: Credit | H1: Remarks
A2: 45839 | C2: Opening Balance | D2: ='June 2025 - Sales'!D147 -> -14611
A3: 45839 | B3: INV-234 | C3: Sales | D3: 410 | F3: Cash
A4: 45839 | B4: INV-235 | C4: Sales | D4: 1330 | F4: Riluwan(Nagore)
A5: 45839 | B5: INV-236 | C5: Sales | D5: 240 | F5: Ansari
A6: 45839 | C6: Expences | E6: 210
A7: 45840 | C7: Ginger Purchase | E7: 2200
A8: 45840 | C8: Expences | E8: 447
A9: 45840 | B9: INV-237 | C9: Sales | D9: 3000 | F9: Riluwan(Nagore)
A10: 45840 | B10: INV-238 | C10: Sales | D10: 80 | F10: Cash
A11: 45841 | C11: Staff Salary | E11: 2000 | H11: Salary Advance - Malar | J11: Row Labels | K11: Sum of Sales | L11: Sum of Expences
A12: 45841 | B12: INV-239 | C12: Sales | D12: 3630 | F12: Riluwan(Nagore) | J12: Opening Balance | K12: -14611
A13: 45841 | B13: INV-240 | C13: Sales | D13: 40 | F13: Cash | J13: Sales | K13: 164755
A14: 45841 | C14: Expences | E14: 25 | J14: Expences | L14: 8384
A15: 45842 | B15: INV-241 | C15: Sales | D15: 40 | F15: Cash | J15: Ginger Purchase | L15: 25600
A16: 45842 | B16: INV-242 | C16: Sales | D16: 3310 | F16: Market Shop | J16: Staff Salary | L16: 10750
A17: 45842 | B17: INV-243 | C17: Sales | D17: 280 | F17: Faisal(Nagai) | J17: Petrol | L17: 1400
A18: 45842 | C18: Expences | E18: 25 | J18: Garlic Purchase | L18: 30735
A19: 45842 | C19: Petrol | E19: 400 | J19: Rent | L19: 9000
A20: 45843 | B20: INV-244 | C20: Sales | D20: 700 | F20: Faisal(Nagai) | J20: Bills | L20: 900
A21: 45843 | B21: INV-245 | C21: Sales | D21: 720 | F21: Market Shop | J21: Others | L21: 2727
A22: 45843 | B22: INV-246 | C22: Sales | D22: 1900 | F22: Riluwan(Nagore) | J22: Grand Total | K22: 150144 | L22: 89496
A23: 45844 | B23: INV-247 | C23: Sales | D23: 480 | F23: Ansari
A24: 45844 | B24: INV-248 | C24: Sales | D24: 180 | F24: Market Shop
A25: 45844 | B25: INV-249 | C25: Sales | D25: 1275 | F25: Riluwan(Nagore) | J25: Gross Revenue | K25: 164755
A26: 45844 | C26: Rent | E26: 9000 | J26: Total | K26: 150144 | L26: 89246
A27: 45845 | B27: INV-250 | C27: Sales | D27: 2240 | F27: Riluwan(Nagore)
A28: 45845 | B28: INV-251 | C28: Sales | D28: 600 | F28: Market Shop | J28: Net Revenue | K28: 75509
A29: 45845 | B29: INV-252 | C29: Sales | D29: 100 | F29: Ansari | J29: Net Balance | K29: 60898
A30: 45845 | C30: Expences | E30: 50
A31: 45846 | B31: INV-253 | C31: Sales | D31: 80 | F31: Cash | J31: Deficit | K31: 17970
A32: 45846 | B32: INV-254 | C32: Sales | D32: 100 | F32: Hassan
A33: 45846 | B33: INV-255 | C33: Sales | D33: 100 | F33: Ansari
A34: 45846 | B34: INV-256 | C34: Sales | D34: 1260 | F34: Market Shop
A35: 45846 | C35: Garlic Purchase | E35: 1800
A36: 45846 | C36: Expences | E36: 25
A37: 45847 | B37: INV-257 | C37: Sales | D37: 3100 | F37: Riluwan(Nagore)
A38: 45847 | B38: INV-258 | C38: Sales | D38: 1650 | F38: Market Shop
A39: 45848 | B39: INV-259 | C39: Sales | D39: 720 | F39: Market Shop
A40: 45848 | B40: INV-260 | C40: Sales | D40: 240 | F40: Ansari
...

Sheet Aug 2025 - Sales
A1: Date | B1: Invoice No | C1: Description | D1: Sales | E1: Expences | F1: Bill To | G1: Variety | H1: Unit Price | I1: Transport cost | J1: Qty | K1: Supplier | L1: Credit | M1: Remarks
C2: Opening Balance | D2: ='July 2025 - Sales'!D150 -> 60648
A3: 45870 | B3: INV-322 | C3: Sales | D3: 340 | F3: Cash
A4: 45870 | B4: INV-323 | C4: Sales | D4: 500 | F4: Riluwan(Nagore)
A5: 45870 | B5: INV-324 | C5: Sales | D5: 100 | F5: Ansari
A6: 45871 | B6: INV-325 | C6: Sales | D6: 350 | F6: Cash
A7: 45871 | B7: INV-326 | C7: Sales | D7: 1920 | F7: Market Shop
A8: 45871 | B8: INV-327 | C8: Sales | D8: 210 | F8: Faisal(Nagai)
A9: 45871 | B9: P-53 | C9: Ginger Purchase | E9: 3900 | G9: Old Ginger | H9: 69.65 | J9: 56 | K9: Jakakodi Traders
A10: 45871 | C10: Expences | E10: 25
A11: 45872 | B11: INV-328 | C11: Sales | D11: 300 | F11: Cash
A12: 45872 | B12: INV-329 | C12: Sales | D12: 675 | F12: Market Shop
A13: 45872 | B13: INV-330 | C13: Sales | D13: 3500 | F13: Riluwan(Nagore)
A14: 45872 | B14: INV-331 | C14: Sales | D14: 2100 | F14: Ansari
A15: 45872 | B15: INV-332 | C15: Sales | D15: 1200 | F15: Cash
A16: 45872 | C16: Delivery charge | E16: 200 | M16: Nagai delivery
A17: 45873 | B17: INV-333 | C17: Sales | D17: 960 | F17: Cash
A18: 45873 | B18: INV-334 | C18: Sales | D18: 570 | F18: Market Shop
A19: 45873 | C19: Expences | E19: 210
A20: 45873 | C20: Petrol | E20: 400
A21: 45874 | B21: INV-335 | C21: Sales | D21: 620 | F21: Cash
A22: 45874 | B22: INV-336 | C22: Sales | D22: 4660 | F22: Market Shop
A23: 45874 | C23: Rent | E23: 9000
A24: 45874 | C24: Others | E24: 644 | M24: Pouch
A25: 45874 | C25: Others | E25: 400 | M25: Sticker 10 Sheets
A26: 45874 | C26: Expences | E26: 50
A27: 45875 | C27: Expences | E27: 50
A28: 45875 | C28: Others | E28: 70 | O28: Row Labels | P28: Sum of Sales | Q28: Sum of Expences
A29: 45875 | C29: Garlic Purchase | E29: 6270 | G29: Desi 4A | H29: 95 | J29: 66 | K29: Nilaa Wholesale Supplies | O29: Opening Balance | P29: 60648
A30: 45875 | C30: Ginger Purchase | E30: 3800 | G30: Old Ginger | H30: 67.85 | J30: 56 | K30: Jakakodi Traders | O30: Sales | P30: 173370
A31: 45875 | B31: INV-337 | C31: Sales | D31: 940 | F31: Cash | O31: Ginger Purchase | Q31: 42800
A32: 45875 | B32: INV-338 | C32: Sales | D32: 3520 | F32: Market Shop | O32: Expences | Q32: 1143
A33: 45877 | B33: INV-339 | C33: Sales | D33: 450 | F33: Cash | O33: Delivery charge | Q33: 1350
A34: 45877 | B34: INV-340 | C34: Sales | D34: 4170 | F34: Market Shop | O34: Petrol | Q34: 2000
A35: 45877 | B35: INV-341 | C35: Sales | D35: 1800 | F35: Barak Vegetables | O35: Rent | Q35: 9000
A36: 45877 | B36: INV-342 | C36: Sales | D36: 300 | F36: Faisal(Nagai) | O36: Others | Q36: 4399
A37: 45876 | B37: INV-343 | C37: Sales | D37: 5400 | F37: Ansari | O37: Garlic Purchase | Q37: 79255
A38: 45876 | B38: INV-344 | C38: Sales | D38: 6075 | F38: Market Shop | O38: Staff Salary | Q38: 11650
A39: 45876 | B39: INV-345 | C39: Sales | D39: 400 | F39: Cash | O39: Water Cane | Q39: 640
A40: 45876 | C40: Delivery charge | E40: 250 | O40: Bills | Q40: 13256
...

Sheet Sep 2025 - Sales 
A1: Date | B1: Invoice No | C1: Description | D1: Sales | E1: Expences | F1: Bill To | G1: Variety | H1: Unit Price | I1: Transport cost | J1: Qty | K1: Supplier | L1: Credit | M1: Remarks
C2: Opening Balance | D2: ='Aug 2025 - Sales'!D162 -> 63725
A3: 45901 | B3: INV-406 | C3: Sales | D3: 340 | F3: Cash
A4: 45901 | B4: INV-407 | C4: Sales | D4: 80 | F4: Hotel Noordeen
A5: 45901 | B5: INV-408 | C5: Sales | D5: 100 | F5: Ansari
A6: 45901 | B6: INV-409 | C6: Sales | D6: 400 | F6: Hassan
A7: 45901 | B7: INV-410 | C7: Sales | D7: 240 | F7: Maraikar Shop
A8: 45901 | B8: INV-411 | C8: Sales | D8: 240 | F8: REAL SUPER MARKET
A9: 45901 | B9: INV-412 | C9: Sales | D9: 1800 | F9: BILAL COOK
A10: 45901 | C10: Expences | E10: 50
A11: 45901 | C11: Packaging Material | E11: 400
A12: 45902 | C12: Ginger Purchase | E12: 3900 | G12: Old Ginger | H12: 78 | J12: 50 | K12: Jakakodi Traders
A13: 45902 | B13: INV-413 | C13: Sales | D13: 1200 | F13: DARBAR CATERING
A14: 45902 | B14: INV-414 | C14: Sales | D14: 1500 | F14: AL AZEEM CATERS & RESTAURANT
A15: 45902 | B15: INV-415 | C15: Sales | D15: 160 | F15: Hotel Noordeen
A16: 45902 | B16: INV-416 | C16: Sales | D16: 90 | F16: Cash
A17: 45902 | B17: INV-417 | C17: Sales | D17: 3000 | F17: AMEEN MASTER CHEF
A18: 45902 | C18: Water Cane | E18: 160
A19: 45902 | C19: Expences | E19: 100
A20: 45903 | B20: INV-418 | C20: Sales | D20: 1200 | F20: HABIL SAHIB
A21: 45903 | C21: Garlic Purchase | E21: 9825 | G21: Naatu Poondu | H21: 75 | I21: 450 | J21: 125 | K21: SVG Garlics
A22: 45903 | C22: Ginger Purchase | E22: 8000 | G22: Old Ginger | H22: 80 | J22: 100 | K22: Jakakodi Traders
A23: 45903 | B23: INV-419 | C23: Sales | D23: 825 | F23: ARAFATH
A24: 45903 | B24: INV-420 | C24: Sales | D24: 600 | F24: VANJUR SHOP MARKET VASAL
A25: 45903 | B25: INV-421 | C25: Sales | D25: 2040 | F25: Cash
A26: 45903 | B26: INV-422 | C26: Sales | D26: 240 | F26: Hotel Noordeen
A27: 45903 | B27: INV-423 | C27: Sales | D27: 2700 | F27: AL AZEEM CATERS & RESTAURANT
A28: 45903 | B28: INV-424 | C28: Sales | D28: 2250 | F28: HASSIM CATERING | O28: Row Labels | P28: Sum of Sales | Q28: Sum of Expences
A29: 45903 | B29: INV-425 | C29: Sales | D29: 3900 | F29: ARAFATH | O29: Opening Balance | P29: 63725
A30: 45903 | B30: INV-426 | C30: Sales | D30: 5120 | F30: ISMAIL BANDARI (THARANGAPADI ) | O30: Sales | P30: 229785
A31: 45903 | B31: INV-427 | C31: Sales | D31: 360 | F31: HOTEL BISMI | O31: Expences | Q31: 1770
A32: 45903 | C32: Expences | E32: 200 | M32: Maligai Kadai | O32: Packaging Material | Q32: 3378
A33: 45903 | C33: Packaging Material | E33: 638 | M33: Ungal Kadai | O33: Ginger Purchase | Q33: 45609
A34: 45903 | C34: Petrol | E34: 400 | O34: Water Cane | Q34: 760
A35: 45903 | C35: Staff Salary | E35: 300 | M35: Tem Staff | O35: Garlic Purchase | Q35: 81350
A36: 45903 | C36: Trasport | E36: 250 | M36: Auto | O36: Petrol | Q36: 1995
A37: 45903 | C37: Expences | E37: 40 | O37: Staff Salary | Q37: 24400
A38: 45904 | B38: INV-428 | C38: Sales | D38: 5700 | F38: Cash | O38: Trasport | Q38: 1250
A39: 45904 | B39: INV-429 | C39: Sales | D39: 8730 | F39: HASSIM CATERING | O39: Delivery charge | Q39: 450
A40: 45904 | B40: INV-430 | C40: Sales | D40: 1500 | F40: AL AZEEM CATERS & RESTAURANT | O40: Rent | Q40: 9000
...

Sheet Oct 2025 - Sales
A1: Date | B1: Invoice No | C1: Description | D1: Sales | E1: Expences | F1: Bill To | G1: Variety | H1: Unit Price | I1: Transport cost | J1: Qty | K1: Supplier | L1: Credit | M1: Remarks
C2: Opening Balance | D2: 0
A3: 45931 | C3: Ginger Purchase | E3: 3700 | G3: Old Ginger | H3: 74 | J3: 50 | K3: Jakakodi Traders
A4: 45931 | B4: INV-652 | C4: Sales | D4: 510 | F4: NFS Delivery
A5: 45931 | B5: INV-653 | C5: Sales | D5: 240 | F5: Hotel Noordeen
A6: 45931 | B6: INV-654 | C6: Sales | D6: 170 | F6: Cash
A7: 45931 | B7: INV-655 | C7: Sales | D7: 320 | F7: Hotel Bismi
A8: 45931 | B8: INV-656 | C8: Sales | D8: 340 | F8: NFS Delivery
A9: 45931 | B9: INV-657 | C9: Sales | D9: 240 | F9: Maraikar Shop
A10: 45931 | B10: INV-658 | C10: Sales | D10: 320 | F10: Darbar Catering
A11: 45931 | B11: INV-659 | C11: Sales | D11: 750 | F11: Arafath
A12: 45931 | B12: INV-660 | C12: Sales | D12: 320 | F12: NFS Delivery
A13: 45931 | C13: Expences | E13: 50
A14: 45931 | C14: Packaging Material | E14: 80
A15: 45931 | C15: Others | E15: 5400
A16: 45932 | B16: INV-661 | C16: Sales | D16: 510 | F16: NFS Delivery
A17: 45932 | B17: INV-662 | C17: Sales | D17: 480 | F17: Hotel Bismi
A18: 45932 | B18: INV-663 | C18: Sales | D18: 170 | F18: Cash
A19: 45932 | B19: INV-664 | C19: Sales | D19: 320 | F19: Malaysian Fast Food
A20: 45932 | B20: INV-665 | C20: Sales | D20: 3000 | F20: Hassim Catering
A21: 45932 | B21: INV-666 | C21: Sales | D21: 160 | F21: Darbar Catering
A22: 45932 | C22: Expences | E22: 50
A23: 45932 | C23: Delivery charge | E23: 100
A24: 45933 | B24: INV-667 | C24: Sales | D24: 320 | F24: Darbar Catering
A25: 45933 | B25: INV-668 | C25: Sales | D25: 1500 | F25: AL AZEEM CATERS & RESTAURANT
A26: 45933 | B26: INV-669 | C26: Sales | D26: 170 | F26: NFS Delivery
A27: 45933 | B27: INV-670 | C27: Sales | D27: 600 | F27: Halidh Cook
A28: 45933 | B28: INV-671 | C28: Sales | D28: 480 | F28: Hotel Bismi | O28: Row Labels | P28: Sum of Sales | Q28: Sum of Expences
A29: 45933 | B29: INV-672 | C29: Sales | D29: 750 | F29: Ameen Master Chef | O29: Opening Balance | P29: 0
A30: 45933 | B30: INV-673 | C30: Sales | D30: 440 | F30: Hotel Noordeen | O30: Ginger Purchase | Q30: 28820
A31: 45933 | B31: INV-674 | C31: Sales | D31: 600 | F31: Habil Sahib | O31: Sales | P31: 171155 | Q31: 0
A32: 45933 | B32: INV-675 | C32: Sales | D32: 240 | F32: RR mini Mart | O32: Expences | Q32: 1445
A33: 45933 | B33: INV-676 | C33: Sales | D33: 260 | F33: Cash | O33: Packaging Material | Q33: 2350
A34: 45933 | B34: INV-677 | C34: Sales | D34: 2250 | F34: Hassim Catering | O34: Others | Q34: 5900
A35: 45933 | B35: INV-678 | C35: Sales | D35: 510 | F35: NFS Delivery | O35: Delivery charge | Q35: 350
A36: 45933 | C36: Expences | E36: 50 | O36: Staff Salary | Q36: 19650
A37: 45934 | B37: INV-679 | C37: Sales | D37: 480 | F37: Supplaykart | O37: Water Cane | Q37: 480
A38: 45934 | B38: INV-680 | C38: Sales | D38: 770 | F38: Cash | O38: Petrol | Q38: 1980
A39: 45934 | B39: INV-681 | C39: Sales | D39: 1500 | F39: AL AZEEM CATERS & RESTAURANT | O39: Rent | Q39: 9000
A40: 45934 | B40: INV-682 | C40: Sales | D40: 4200 | F40: Ameen Master Chef | O40: Essential Items | Q40: 1687
...

Sheet Nov 2025 - Sales
A1: Date | B1: Invoice No | C1: Description | D1: Sales | E1: Expences | F1: Bill To | G1: Variety | H1: Unit Price | I1: Transport cost | J1: Qty | K1: Supplier | L1: Credit | M1: Remarks
C2: Opening Balance | D2: ='Oct 2025 - Sales'!D353 -> 39169
A3: 45962 | C3: Ginger Purchase | E3: 3300 | G3: Old Ginger | H3: 66 | J3: 50 | K3: Jakakodi Traders
A4: 45962 | B4: INV-923 | C4: Sales | D4: 1350 | F4: AMEEN MASTER CHEF
A5: 45962 | B5: INV-924 | C5: Sales | D5: 240 | F5: HOTEL NOORDEEN
A6: 45962 | B6: INV-925 | C6: Sales | D6: 400 | F6: CHENNAI TAWA BEEF
A7: 45962 | B7: INV-926 | C7: Sales | D7: 160 | F7: FAISAL(NAGAI)
A8: 45962 | B8: INV-927 | C8: Sales | D8: 320 | F8: HOTEL BISMI
A9: 45962 | B9: INV-928 | C9: Sales | D9: 240 | F9: MARAIKAR SHOP
A10: 45962 | B10: INV-929 | C10: Sales | D10: 80 | F10: SUPPLAYKART
A11: 45962 | B11: INV-930 | C11: Sales | D11: 1500 | F11: AL AZEEM CATERS & RESTAURANT
A12: 45962 | B12: INV-931 | C12: Sales | D12: 2250 | F12: HALIDH COOK
A13: 45962 | B13: INV-932 | C13: Sales | D13: 480 | F13: AMEEN MASTER CHEF
A14: 45962 | B14: INV-933 | C14: Sales | D14: 640 | F14: CASH
A15: 45962 | B15: INV-934 | C15: Sales | D15: 320 | F15: HOTEL NOORDEEN
... A18: 45962 | B18: INV-937 | C18: Sales | D18: 1500 | F18: UMAR BRIYANI
A19: 45962 | C19: Staff Salary | E19: 100
A20: 45962 | C20: Expences | E20: 50
A21: 45963 | B21: INV-938 | C21: Sales | D21: 320 | F21: HOTEL BISMI
A22: 45963 | B22: INV-939 | C22: Sales | D22: 1500 | F22: HASSIM CATERING
A23: 45963 | B23: INV-940 | C23: Sales | D23: 1500 | F23: AL AZEEM CATERS & RESTAURANT
A24: 45963 | B24: INV-941 | C24: Sales | D24: 660 | F24: NFS DELIVERY
A25: 45963 | B25: INV-942 | C25: Sales | D25: 480 | F25: CASH
A26: 45964 | B26: INV-943 | C26: Sales | D26: 280 | F26: HOTEL NOORDEEN
A27: 45964 | B27: INV-944 | C27: Sales | D27: 100 | F27: ANSARI
A28: 45964 | B28: INV-945 | C28: Sales | D28: 320 | F28: HOTEL BISMI | O28: Row Labels | P28: Sum of Sales | Q28: Sum of Expences
A29: 45964 | B29: INV-946 | C29: Sales | D29: 1500 | F29: LE ROYAL MANDI | O29: Opening Balance | P29: 39169
A30: 45964 | B30: INV-947 | C30: Sales | D30: 240 | F30: MARAIKAR SHOP | O30: (blank)
A31: 45964 | B31: INV-948 | C31: Sales | D31: 150 | F31: CASH | O31: Ginger Purchase | Q31: 30310.5
A32: 45964 | B32: INV-949 | C32: Sales | D32: 750 | F32: HASSIM CATERING | O32: Sales | P32: 178135
A33: 45964 | C33: Expences | E33: 50 | O33: Staff Salary | Q33: 16770
A34: 45964 | C34: Water Cane | E34: 160 | O34: Expences | Q34: 1240
A35: 45965 | C35: Ginger Purchase | E35: 1810.5 | G35: Old Ginger | H35: 60.35 | J35: 30 | K35: Jakakodi Traders | O35: Water Cane | Q35: 480
A36: 45965 | B36: INV-950 | C36: Sales | D36: 240 | F36: HOTEL NOORDEEN | O36: Rent | Q36: 9000
A37: 45965 | B37: INV-951 | C37: Sales | D37: 320 | F37: CHENNAI TAWA BEEF | O37: Essential Items | Q37: 320
A38: 45965 | B38: INV-952 | C38: Sales | D38: 320 | F38: HOTEL BISMI | O38: Delivery charge | Q38: 758
A39: 45965 | B39: INV-953 | C39: Sales | D39: 90 | F39: NFS DELIVERY | O39: Packaging Material | Q39: 3860
A40: 45965 | B40: INV-954 | C40: Sales | D40: 80 | F40: BURHAAN | O40: Petrol | Q40: 1600
A41: 45965 | B41: INV-955 | C41: Sales | D41: 1500 | F41: HASSIM CATERING | O41: Garlic Purchase | Q41: 51012
A42: 45965 | C42: Staff Salary | E42: 100 | O42: Others | Q42: 480
...

Sheet Dec 2025 - Sales
A1: Date | B1: Invoice No | C1: Description | D1: Sales | E1: Expences | F1: Bill To | G1: Variety | H1: Unit Price | I1: Transport cost | J1: Qty | K1: Supplier | L1: Credit | M1: Remarks
C2: Opening Balance | D2: ='Nov 2025 - Sales'!D321 -> 60995.5
A3: 45992 | B3: INV-1165 | C3: Sales | D3: 1280 | F3: HOTEL BISMI
A4: 45992 | B4: INV-1166 | C4: Sales | D4: 320 | F4: SAHABUDEEN
A5: 45992 | B5: INV-1167 | C5: Sales | D5: 800 | F5: CHENNAI TAWA BEEF
A6: 45992 | B6: INV-1168 | C6: Sales | D6: 160 | F6: NOORDIN FOOD COURT
A7: 45992 | B7: INV-1169 | C7: Sales | D7: 300 | F7: HASSAN
A8: 45992 | B8: INV-1170 | C8: Sales | D8: 2250 | F8: LE ROYAL MANDI
A9: 45992 | B9: INV-1171 | C9: Sales | D9: 90 | F9: Cash
A10: 45992 | B10: INV-1172 | C10: Sales | D10: 170 | F10: NFS DELIVERY
A11: 45992 | B11: INV-1173 | C11: Sales | D11: 160 | F11: BURHAAN
A12: 45992 | B12: INV-1174 | C12: Sales | D12: 640 | F12: HALIDH COOK
A13: 45992 | B13: INV-1175 | C13: Sales | D13: 1500 | F13: HASSIM CATERING
A14: 45992 | C14: Expences | E14: 30 | M14: Bike Repair
A15: 45992 | C15: Water Cane | E15: 160
A16: 45992 | C16: Expences | E16: 50
A17: 45992 | C17: Packaging Material | E17: 430
A18: 45993 | C18: Ginger Purchase | E18: 3400 | G18: Old Ginger | H18: 68 | J18: 50 | K18: Jakakodi Traders
A19: 45993 | C19: Staff Salary | E19: 500 | M19: Saranya Salary advance
A20: 45993 | B20: INV-1176 | C20: Sales | D20: 1500 | F20: ARAFA RESTAURANT
A21: 45993 | B21: INV-1177 | C21: Sales | D21: 260 | F21: Cash
A22: 45993 | B22: INV-1178 | C22: Sales | D22: 240 | F22: NOORDIN FOOD COURT
A23: 45993 | B23: INV-1179 | C23: Sales | D23: 160 | F23: RR MINI MART
A24: 45993 | B24: INV-1180 | C24: Sales | D24: 320 | F24: HOTEL BISMI
A25: 45993 | B25: INV-1181 | C25: Sales | D25: 750 | F25: AR RAHIM HOTEL
A26: 45993 | B26: INV-1182 | C26: Sales | D26: 160 | F26: SUPPLAYKART
A27: 45993 | B27: INV-1183 | C27: Sales | D27: 320 | F27: BURHAAN
A28: 45993 | B28: INV-1184 | C28: Sales | D28: 750 | F28: HASSIM CATERING
A29: 45993 | B29: INV-1185 | C29: Sales | D29: 750 | F29: AMEEN MASTER CHEF | O29: Row Labels | P29: Sum of Sales | Q29: Sum of Expences
A30: 45993 | C30: Expences | E30: 50 | O30: Opening Balance | P30: 60995.5
A31: 45994 | B31: INV-1186 | C31: Sales | D31: 750 | F31: AMEEN MASTER CHEF | O31: (blank)
A32: 45994 | B32: INV-1187 | C32: Sales | D32: 320 | F32: HOTEL BISMI | O32: Sales | P32: 78870
A33: 45994 | B33: INV-1188 | C33: Sales | D33: 320 | F33: MALAYSIAN FAST FOOD | O33: Expences | Q33: 500
A34: 45994 | B34: INV-1189 | C34: Sales | D34: 340 | F34: NFS DELIVERY | O34: Water Cane | Q34: 320
A35: 45994 | B35: INV-1190 | C35: Sales | D35: 1500 | F35: HASSIM CATERING | O35: Packaging Material | Q35: 1020
A36: 45994 | B36: INV-1191 | C36: Sales | D36: 1350 | F36: HABIL SAHIB | O36: Ginger Purchase | Q36: 10300
A37: 45994 | B37: INV-1192 | C37: Sales | D37: 220 | F37: NOORDIN FOOD COURT | O37: Delivery charge | Q37: 600
A38: 45994 | B38: INV-1193 | C38: Sales | D38: 150 | F38: HASSAN | O38: Others | Q38: 8610
A39: 45994 | B39: INV-1194 | C39: Sales | D39: 1600 | F39: AL AZEEM CATERS & RESTAURANT | O39: Rent | Q39: 9000
A40: 45994 | C40: Delivery charge | E40: 50 | O40: Petrol | Q40: 770
...

Sheet P&L - 2025
A3: Profit & Loss - 2025
A5: Month | B5: Sales | C5: Expences | D5: Gross Revenue | E5: Gross Profit | F5: Net Profit
A6: 45689 | B6: ='Feb 2025 - Sales'!C24 -> 21450 | C6: ='Feb 2025 - Sales'!D25 -> 26975 | D6: =B6 -> 21450 | F6: =D6-C6 -> -5525
A7: 45717 | B7: ='Mar 2025 - Sales'!D128 -> 188580 | C7: ='Mar 2025 - Sales'!E129 -> 162135 | D7: =B7 -> 188580 | F7: =D7-C7 -> 26445
A8: 45748 | B8: ='Apr 2025 - Sales'!D104 -> 105060 | C8: ='Apr 2025 - Sales'!E105 -> 114833 | D8: =B8 -> 105060 | F8: =D8-C8 -> -9773
A9: 45778 | B9: ='May 2025 - Sales'!D133 -> 133160 | C9: ='May 2025 - Sales'!E134 -> 154562 | D9: =B9 -> 133160 | F9: =D9-C9 -> -21402
A10: 45809 | B10: ='June 2025 - Sales'!D143 -> 126385 | C10: ='June 2025 - Sales'!E144 -> 173669 | D10: =B10 -> 126385 | F10: =D10-C10 -> -47284
A11: 45839 | B11: ='July 2025 - Sales'!D146 -> 164755 | C11: ='July 2025 - Sales'!E147 -> 89496 | D11: =B11 -> 164755 | F11: =D11-C11 -> 75259
A12: 45870 | B12: ='Aug 2025 - Sales'!D158 -> 173370 | C12: ='Aug 2025 - Sales'!E159 -> 170293 | D12: ='Aug 2025 - Sales'!D158 -> 173370 | F12: =D12-C12 -> 3077
A13: 45901 | B13: ='Sep 2025 - Sales '!D341 -> 229785 | C13: ='Sep 2025 - Sales '!E342 -> 173935 | D13: =B13 -> 229785 | F13: =D13-C13 -> 55850
A14: 45931 | B14: ='Oct 2025 - Sales'!D349 -> 171155 | C14: ='Oct 2025 - Sales'!E350 -> 131986 | D14: =B14 -> 171155 | F14: =D14-C14 -> 39169
A15: 45962 | B15: ='Nov 2025 - Sales'!D318 -> 178135 | C15: ='Nov 2025 - Sales'!E319 -> 117139.5 | D15: =B15 -> 178135 | F15: =D15-C15 -> 60995.5
A16: 45992 | B16: ='Dec 2025 - Sales'!D241 -> 139760 | C16: ='Dec 2025 - Sales'!E242 -> 107266 | D16: =B16 -> 139760 | F16: =D16-C16 -> 32494
A18: Total | B18: =SUM(B6:B17) -> 1631595 | C18: =SUM(C6:C17) -> 1422289.5 | D18: =SUM(D6:D17) -> 1631595 | E18: =SUM(E6:E17) -> 0 | F18: =SUM(F6:F17) -> 209305.5
L19: Row Labels | M19: Sum of Sales | N19: Sum of Expences
L20: 45689 | M20: 21450 | N20: 26975
L21: 45717 | M21: 188580 | N21: 162135
L22: 45748 | M22: 105060 | N22: 114833
A23: Profit Share | L23: 45778 | M23: 133160 | N23: 154562
B24: Nassar | E24: Ansari | H24: Hassan | L24: 45809 | M24: 126385 | N24: 173669
A25: Month | B25: Share | C25: Paid | D25: Balance | E25: Share | F25: Paid | G25: Balance | H25: Share | I25: Paid | J25: Balance | L25: 45839 | M25: 164755 | N25: 89496
A26: 45689 | B26: =(F6/4)*2 -> -2762.5 | C26: 0 | D26: 0 | E26: =(F6/4)*1 -> -1381.25 | F26: 0 | G26: 0 | H26: =(F6/4)*1 -> -1381.25 | I26: 0 | J26: 0 | L26: 45870 | M26: 173370 | N26: 170293
A27: 45717 | B27: =(F7/4)*2 -> 13222.5 | C27: 10460 | D27: =B27-C27 -> 2762.5 | E27: =(F7/4)*1 -> 6611.25 | F27: 5000 | G27: =E27-F27 -> 1611.25 | H27: =(F7/4)*1 -> 6611.25 | I27: 5000 | J27: =H27-I27 -> 1611.25 | L27: 45901 | M27: 229785 | N27: 173935
A28: 45748 | B28: =(F8/4)*2 -> -4886.5 | C28: 0 | D28: 0 | E28: =(F8/4)*1 -> -2443.25 | F28: 0 | G28: 0 | H28: =(F8/4)*1 -> -2443.25 | I28: 0 | J28: 0 | L28: 45931 | M28: 171155 | N28: 131986
A29: 45778 | B29: =(F9/4)*2 -> -10701 | C29: 0 | D29: 0 | E29: =(F9/4)*1 -> -5350.5 | F29: 0 | G29: 0 | H29: =(F9/4)*1 -> -5350.5 | I29: 0 | J29: 0 | L29: 45962 | M29: 178135 | N29: 117139.5
A30: 45809 | B30: =(F10/4)*2 -> -23642 | C30: 0 | D30: 0 | E30: =(F10/4)*1 -> -11821 | F30: 0 | G30: 0 | H30: =(F10/4)*1 -> -11821 | I30: 0 | J30: 0 | L30: 45992 | M30: 139760 | N30: 107266
A31: 45839 | B31: =(F11/4)*2 -> 37629.5 | C31: 0 | D31: 0 | E31: =(F11/4)*1 -> 18814.75 | F31: 0 | G31: 0 | H31: =(F11/4)*1 -> 18814.75 | I31: 0 | J31: 0 | L31: Grand Total | M31: 1631595 | N31: 1422289.5
A32: 45870 | B32: =(F12/4)*2 -> 1538.5 | C32: 0 | D32: 0 | E32: =(F12/4)*1 -> 769.25 | F32: 0 | G32: 0 | H32: =(F12/4)*1 -> 769.25 | I32: 0 | J32: 0
A33: 45901
A34: 45931
A35: 45962
A36: 45992
A38: Total | B38: =SUM(B26:B36) -> 10398.5 | C38: =SUM(C26:C36) -> 10460 | D38: =B38-C38 -> -61.5 | E38: =SUM(E26:E36) -> 5199.25 | F38: =SUM(F26:F36) -> 5000 | G38: =E38-F38 -> 199.25 | H38: =SUM(H26:H36) -> 5199.25 | I38: =SUM(I26:I36) -> 5000 | J38: =H38-I38 -> 199.25
A40: Total Share Paid | B40: =C38+F38+I38 -> 20460

Sheet Sheet2
A1: Advance | B1: Garlic | C1: Jakakodi Traders | D1: ANSARI | E1: Desi 2A
A2: Bills | B2: Ginger | C2: Mass Traders | D2: AHEE BANDARI | E2: Desi 3A
A3: Customer deposit refund | C3: Nilaa Wholesale Supplies | D3: AL AZEEM CATERS & RESTAURANT | E3: Desi 4A
A4: Delivery charge | C4: PK Garlic | D4: AL AZEEM CATERS & RESTAURANT | E4: Desi Bom size
A5: Essential Items | C5: SVG Garlics | D5: AL BAIK MANDI | E5: Desi Udiri
A6: Expences | D6: AL RAYAAN MANDI | E6: Naatu Poondu
A7: Garlic Purchase | D7: AMEEN MASTER CHEF | E7: Old Ginger
A8: Ginger Purchase | D8: ANDREW COOK | E8: Ooty Seed A
A9: Loan | D9: AR RAHIM HOTEL
A10: Machinary Maintenance | D10: ARAFA RESTAURANT
A11: Marketting | D11: ARAFATH
A12: Others | D12: Badhru Idli Kadai
A13: Packaging Material | D13: BARAK VEGETABLES
A14: Petrol | D14: BAVA CHEF
A15: Rent | D15: BILAL COOK
A16: Sales | D16: BURHAAN
A17: Staff Salary | D17: CASH
A18: Trasport | D18: CHENNAI TAWA BEEF
A19: Water Cane | D19: DARBAR CATERING
D20: DIAMOND LODGE
D21: FAISAL(NAGAI)
D22: FAIZAL NAGAI
D23: HABEEB
D24: HABIL SAHIB
D25: HALIDH COOK
D26: HASSAN
D27: HASSIM CATERING
D28: HOTEL ANAS
D29: HOTEL BISMI
D30: HOTEL LEBBAI
D31: HOTEL NOORDEEN
... D61: SADAM BANDARI

Sheet Sheet1
E1: Nila Foods & Spices
A2: Daily Stock & Production
A4: Stock-in | E4: Pre-Production | I4: Post-Production
A5: Date | B5: Material | C5: Weight(Kgs) | E5: Date | F5: Material | G5: Weight(Kgs) | I5: Date | J5: Material | K5: Weight(Kgs)
B6: Ginger / Garlic | F6: Ginger / Garlic | J6: Paste / Peeled

Sheet Sheet3
J5: With Citrix acid
J7: NUTRITIONAL INFORMATION* Per 100g of the Product (Approx) | L7: Nutritional Information per Serving -10g | M7: % Daily Values Per serving (10g)
D9: Month | E9: Ansari's Invoice Balances | G9: Expences | J9: Energy | K9: 99 Kcal | L9: 9.9 Kcal | M9: 0.0043
D10: 45809 | F10: 1300 | J10: Protein | K10: 4.16 g | L10: 0.41 g | M10: ~
D11: 45809 | F11: 2240 | J11: Fiber | K11: 4.95 g | L11: 0.49 g | M11: ~
D12: 45809 | F12: 200 | J12: Carbohydrate | K12: 13.8 g | L12: 1.38 g | M12: ~
D13: 45809 | F13: 600 | J13: Total Sugar | K13: NIL | L13: NIL | M13: 0
D14: 45809 | F14: 960 | J14: Total Fat | K14: 2.97 g | L14: 0.29 g | M14: 0.0013
D15: 45839 | E15: MGK Invoice | F15: 8000 | J15: Trans Fat Not more than | K15: NIL | L15: NIL | M15: ~
E16: FSSAI Expences | G16: 9636 | J16: Cholesterol | K16: NIL | L16: NIL | M16: ~
E17: Machine Belt | G17: 680 | J17: Sodium | K17: 212 mg | L17: 21.2 mg | M17: 0.0139
E18: FSSAI Frame | G18: 100 | J18: Calcium | K18: 11 mg | L18: 1.1 mg | M18: ~
E19: Petrol | G19: 200 | J19: Iron | K19: 0.16 mg | L19: 0.01 mg | M19: ~
E20: Malar Salary Ad | G20: 3000 | J20: *Source: NIN-Nutritive Value of Indian Foods
D21: Total | F21: =SUM(F10:F19) -> 13300 | G21: =SUM(G16:G20) -> 13616 | J21: **Percent Daily Values are based on a 2,000 calorie Diet. Your daily values may be higher or lower depending on your calorie need
D22: Balance | G22: =F21-G21 -> -316
A29: 45839
A30: Date | B30: Invoice No. | C30: Customer | D30: Amount | E30: Payment Status | F30: Balance | G30: Customer
A31: 45839 | B31: INV-236 | C31: ANSARI ( PARTNER ) | D31: 240
A32: 45844 | B32: INV-247 | C32: ANSARI ( PARTNER ) | D32: 480
A33: 45845 | B33: INV-252 | C33: ANSARI ( PARTNER ) | D33: 100 | E33: Paid
A34: 45846 | B34: INV-255 | C34: ANSARI ( PARTNER ) | D34: 100 | E34: Paid
A35: 45848 | B35: INV-260 | C35: ANSARI ( PARTNER ) | D35: 240
A36: 45849 | B36: INV-265 | C36: ANSARI ( PARTNER ) | D36: 8160 | E36: Paid | G36: 8000 Paid MGK
A37: 45857 | B37: INV-286 | C37: ANSARI ( PARTNER ) | D37: 4500 | E37: Paid | F37: 4950 | G37: Bava Mandi
A38: 45861 | B38: INV-300 | C38: ANSARI ( PARTNER ) | D38: 200 | E38: Paid
A39: 45866 | B39: INV-311 | C39: ANSARI ( PARTNER ) | D39: 6000 | E39: Paid | F39: 5700 | G39: Peerodam St, 300 Auto
C40: Total | D40: =SUM(D31:D39) -> 20020 | I40: 19500
I41: 8240
A42: 45870
A43: Date | B43: Invoice No | C43: Customer | D43: Amount | E43: Payment Status | G43: Customer
A44: 45870 | B44: INV-324 | C44: ANSARI ( PARTNER ) | D44: 100 | E44: Paid
A45: 45872 | B45: INV-331 | C45: ANSARI ( PARTNER ) | D45: 2100 | E45: 1700 Paid | F45: 400 | G45: RS 1700 Paid Nagai delivery
A46: 45876 | B46: INV-343 | C46: ANSARI ( PARTNER ) | D46: 5400 | E46: 3000 Paid | F46: 2400 | G46: 16kg Rs 2400 Shaha Malim Rs 3000 M Palli | J46: 3000
A47: 45878 | B47: INV-348 | C47: ANSARI ( PARTNER ) | D47: 13500 | F47: 13500 | G47: 90 Shaha Malim | J47: 900
A48: 45879 | B48: INV-350 | C48: ANSARI ( PARTNER ) | D48: 3600 | F48: 3600 | G48: 24 Saha Malim | J48: 1700
A49: 45882 | B49: INV-359 | C49: ANSARI ( PARTNER ) | E49: 900 Paid | F49: 460 | G49: 6kg Sulaiman 900 Paid 4kg Nagai 460 Unpaid | J49: 5700
C50: Total | D50: =SUM(D44:D48) -> 24700 | J50: 4950 | K50: Paid
C52: Jul & Aug Total | D52: =SUM(D50,D40) -> 44720
I55: 37690 | J55: 19500
...

Sheet DashBoard
A4: Sales Dashboard

Sheet Sheet5
A2: August | D2: July
A3: Values | D3: Values
A4: Count of Invoice No | B4: 88 | D4: Count of Invoice No | E4: 90
A5: Sum of Sales | B5: 234018 | D5: Sum of Sales | E5: 150144
A6: Sum of Expences | B6: 170293 | D6: Sum of Expences | E6: 89496
