Workbook

Sheet Summary
B2: Stock
C3: July & Aug | F3: Aug & Sep | I3: Sep & Oct
B4: Material | C4: Closing stock | D4: Opening stock | E4: Difference | F4: Closing Stock | G4: Opening stock | H4: Difference | I4: Closing Stock | J4: Opening stock | K4: Difference
B5: Ginger | C5: ='July 2025'!O35 -> 33.65 | D5: ='Aug 2025'!C6 -> 0 | E5: =C5-D5 -> 33.65 | F5: ='Aug 2025'!O35 -> 134.65 | G5: ='Sep 2025'!C6 -> 23.9 | H5: =F5-G5 -> 110.75 | I5: ='Sep 2025'!O35 -> 82.66 | J5: ='Oct 2025'!C6 -> 4.63 | K5: =I5-J5 -> 78.03
B6: Garlic | C6: ='July 2025'!O36 -> 196.46 | D6: ='Aug 2025'!C7 -> 75.3 | E6: =C6-D6 -> 121.16 | F6: ='Aug 2025'!O36 -> 103.28 | G6: ='Sep 2025'!C7 -> 116.8 | H6: =F6-G6 -> -13.52 | I6: ='Sep 2025'!O36 -> 351.23 | J6: ='Oct 2025'!C7 -> 298.03 | K6: =I6-J6 -> 53.2
B7: Ginger Peeled | D7: ='Aug 2025'!C10 -> 0 | G7: ='Sep 2025'!C10 -> 0 | J7: ='Oct 2025'!C10 -> 0
B8: Garlic Peeled | D8: ='Aug 2025'!C9 -> 12 | G8: ='Sep 2025'!C9 -> 12 | J8: ='Oct 2025'!C9 -> 0
B9: Ginger Garlic Paste | D9: ='Aug 2025'!C8 -> 72 | G9: ='Sep 2025'!C8 -> 100 | J9: ='Oct 2025'!C8 -> 111.22
B10: Ginger Paste | D10: ='Aug 2025'!C13 -> 0 | G10: ='Sep 2025'!C13 -> 0 | J10: ='Oct 2025'!C13 -> 0
B11: Garlic Paste | D11: ='Aug 2025'!C14 -> 0 | G11: ='Sep 2025'!C14 -> 0 | J11: ='Oct 2025'!C14 -> 0
B15: Production & Sales Kgs
C16: July | G16: August | K16: September
B17: Material | C17: Production | D17: Sales | E17: Aug OS | F17: Difference | G17: Production | H17: Sales | I17: Sep OS | J17: Difference | K17: Production | L17: Sales | M17: Oct OS | N17: Difference
B18: Ginger Peeled | C18: ='July 2025'!P28 -> 0.5 | D18: 1.5 | E18: =G7 -> 0 | G18: ='Aug 2025'!P28 -> 3 | H18: 6.75 | I18: =G7 -> 0 | J18: =G18-H18 -> -3.75 | K18: ='Sep 2025'!P28 -> 11.5 | L18: 2 | M18: =J7 -> 0 | N18: =K18-L18 -> 9.5
B19: Garlic Peeled | C19: ='July 2025'!P29 -> 185.5 | D19: 165.5 | E19: =G8 -> 12 | G19: ='Aug 2025'!P29 -> 106.5 | H19: 257.75 | I19: =G8 -> 12 | J19: =(G19-H19)-I19 -> -163.25 | K19: ='Sep 2025'!P29 -> 109 | L19: 151 | M19: =J8 -> 0 | N19: =(K19-L19)-M19 -> -42
B20: Ginger Garlic Paste | C20: ='July 2025'!P30 -> 1184.3 | D20: 870 | E20: =G9 -> 100 | G20: ='Aug 2025'!P30 -> 1272.27 | H20: 1072.25 | I20: =G9 -> 100 | J20: =(G20-H20)-I20 -> 100.02 | K20: ='Sep 2025'!P30 -> 1598.89 | L20: 1279.2 | M20: =J9 -> 111.22 | N20: =(K20-L20)-M20 -> 208.47
B21: Ginger Paste | C21: ='July 2025'!P31 -> 2 | D21: 30.5 | E21: =G10 -> 0 | G21: ='Aug 2025'!P31 -> 0 | H21: 10 | I21: =G10 -> 0 | J21: =G21-H21 -> -10 | K21: ='Sep 2025'!P31 -> 21 | L21: 0 | M21: =J10 -> 0 | N21: =(K21-L21)-M21 -> 21
B22: Garlic Paste | C22: ='July 2025'!P32 -> 0 | D22: 256.5 | E22: =G11 -> 0 | G22: ='Aug 2025'!P32 -> 0 | H22: 10.5 | I22: =G11 -> 0 | J22: =G22-H22 -> -10.5 | K22: ='Sep 2025'!P32 -> 21 | L22: 0 | M22: =J11 -> 0 | N22: =(K22-L22)-M22 -> 21
G26: 1272
G27: 1072

Sheet April 2025
A1: NFS@2025 | E1: Nila Foods & Spices
A2: Daily Stock & Production | C2: 45748
A4: Stock-in | E4: Pre-Production | I4: Post-Production
A5: Date | B5: Material | C5: Weight(Kgs) | E5: Date | F5: Material | G5: Weight(Kgs) | I5: Date | J5: Material | K5: Weight(Kgs)
A6: 45765 | B6: Garlic | C6: 129 | E6: 45765 | F6: Ginger | G6: 10 | J6: Ginger Peeled | K6: 8.5 | N6: Available Stock | O6: Total(Kgs)
A7: 45765 | B7: Ginger | C7: 37.45 | E7: 45765 | F7: Garlic | G7: 30 | J7: Garlic Peeled | K7: 27 | N7: Ginger | O7: =SUMIF(B6:B124,"Ginger",C6:C124) -> 147.45
A8: 45765 | B8: Garlic | C8: 87 | E8: 45765 | F8: Ginger | G8: 7 | J8: Ginger Peeled | K8: 6.1 | N8: Garlic | O8: =SUMIF(B7:B125,"Garlic",C7:C125) -> 317.5
A9: 45770 | B9: Garlic | C9: 192 | E9: 45766 | F9: Garlic | G9: 20 | J9: Garlic Peeled | K9: 17.5 | N9: Broken Garlic | O9: =SUMIF(B8:B126,"Broken Garlic",C8:C126) -> 37.4
A10: 45770 | B10: Ginger | C10: 56 | E10: 45766 | F10: Ginger | G10: 15 | J10: Ginger Peeled | K10: 13.1
E11: 45767 | F11: Ginger | G11: 15 | J11: Ginger Peeled | K11: 13.7
E12: 45767 | F12: Garlic | G12: 30 | J12: Garlic Peeled | K12: 26 | N12: Pre-Production | O12: Total(Kgs)
E13: 45767 | F13: Ginger | G13: 6 | J13: Ginger Peeled | K13: 5.1 | N13: Ginger | O13: =SUMIF(F6:F130,"Ginger",G6:G130) -> 153
E14: 45768 | F14: Ginger | G14: 10 | J14: Ginger Peeled | K14: 9 | N14: Garlic | O14: =SUMIF(F6:F124,"Garlic",G6:G124) -> 180.3
E15: 45769 | F15: Garlic | G15: 20 | J15: Garlic Peeled | K15: 18 | N15: Broken Garlic | O15: =SUMIF(F6:F124,"Broken Garlic",G6:G124) -> 22
E16: 45769 | F16: Garlic | G16: 34.5 | J16: Garlic Peeled | K16: 29
E17: 45771 | F17: Ginger | G17: 20 | J17: Garlic Peeled | K17: 18.5
E18: 45771 | F18: Garlic | G18: 20 | J18: Garlic Peeled | K18: 16.15 | N18: Post-Production | O18: Total(Kgs)
A19: 45771 | B19: Broken Garlic | C19: 3 | E19: 45772 | F19: Ginger | G19: 20 | I19: 45772 | J19: Ginger Peeled | K19: 17.5 | N19: Ginger Peeled | O19: =SUMIF(J6:J124,"Ginger Peeled",K6:K124) -> 73
B20: Broken Garlic | C20: 10 | I20: 45773 | J20: Ginger Garlic Paste | K20: 15.73 | N20: Garlic Peeled | O20: =SUMIF(J6:J124,"Garlic Peeled",K6:K124) -> 156.15
B21: Broken Garlic | C21: 8.9 | I21: 45773 | J21: Garlic Peeled | K21: 4 | N21: Ginger Garlic Paste | O21: =SUMIF(J6:J124,"Ginger Garlic Paste",K6:K124) -> 135.32
B22: Ginger | C22: 54 | I22: 45773 | J22: Ginger Garlic Paste | K22: 11.7
E23: 45775 | F23: Broken Garlic | G23: 22 | I23: 45775 | J23: Ginger Garlic Paste | K23: 20.13
E24: 45775 | F24: Ginger | G24: 18 | I24: 45775 | J24: Ginger Garlic Paste | K24: 23.36
E25: 45775 | F25: Ginger | G25: 6 | I25: 45775 | J25: Ginger Garlic Paste | K25: 11.5
E26: 29/4/2025 | F26: Ginger | G26: 15.5 | I26: 29/4/2025 | J26: Ginger Garlic Paste | K26: 17.3
E27: 29/4/2025 | F27: Garlic | G27: 15 | I27: 29/4/2025 | J27: Ginger Garlic Paste | K27: 12.4
A28: 45777 | B28: Broken Garlic | C28: 15.5 | E28: 30/4/2025 | F28: Ginger | G28: 10.5 | I28: 30/4/2025 | J28: Ginger Garlic Paste | K28: 23.2
B29: Garlic | C29: 38.5 | E29: 30/4/2025 | F29: Garlic | G29: 10.8

Sheet May 2025
E1: Nila Foods & Spices
A2: Daily Stock & Production | C2: 45778
A4: Stock-in | E4: Pre-Production | I4: Post-Production
A5: Date | B5: Material | C5: Weight(Kgs) | E5: Date | F5: Material | G5: Weight(Kgs) | I5: Date | J5: Material | K5: Weight(Kgs)
A6: 45778 | B6: OS - Garlic | C6: 77 | E6: 45778 | F6: Garlic | G6: 38.5 | I6: 45778 | J6: Ginger Garlic Paste | K6: 30.5
B7: Ginger | C7: 8 | E7: 45779 | F7: Ginger | G7: 16.5 | I7: 45779 | J7: Ginger Garlic Paste | K7: 35.37 | T7: S.No. | U7: Item | V7: Qty. | W7: Kgs | X7: Total Amount
B8: Ginger | C8: 54 | I8: 45780 | J8: Ginger Garlic Paste | K8: 19.3 | N8: Available Stock | O8: Total(Kgs) | T8: 1 | U8: GINGER GARLIC PASTE 1KG | V8: 845 | W8: =V8 -> 845 | X8: 99355
A9: 45779 | B9: Broken Garlic | C9: 21.5 | I9: 45782 | J9: Ginger Garlic Paste | K9: 22.1 | N9: OS - Garlic | O9: =SUMIF(B6:B124,"Os - Garlic",C6:C124) -> 77 | T9: 2 | U9: NFS PEELED GARLIC 1KG | V9: 170 | W9: =V9 -> 170 | X9: 23880
A10: 45780 | B10: Broken Garlic | C10: 33.4 | I10: 45782 | J10: Ginger Garlic Paste | K10: 16.8 | N10: OS - Ginger | O10: =SUMIF(B6:B124,"Os - Ginger",C6:C124) -> 0 | T10: 3 | U10: NFS GINGER GARLIC PASTE (250 GMS) | V10: 77 | W10: =V10/4 -> 19.25 | X10: 2430
A11: 45781 | B11: Garlic | C11: 220 | I11: 45783 | J11: Ginger Garlic Paste | K11: 21 | N11: Ginger | O11: =SUMIF(B6:B124,"Ginger",C6:C124) -> 402.5 | T11: 4 | U11: NFS PEELED GINGER | V11: 4 | W11: =V11 -> 4 | X11: 270
A12: 45782 | B12: Broken Garlic | C12: 31.5 | E12: 45782 | F12: Ginger | G12: 15.83 | I12: 45783 | J12: Ginger Garlic Paste | K12: 9.5 | N12: Garlic | O12: =SUMIF(B6:B124,"Garlic",C6:C124) -> 632 | T12: 5 | U12: NFS PEELED GARLIC ( 500 GRM ) | V12: 2 | W12: =V12/2 -> 1 | X12: 165
A13: 45783 | B13: Broken Garlic | C13: 18.5 | E13: 45783 | F13: Ginger | G13: 18.86 | I13: 45784 | J13: Ginger Garlic Paste | K13: 15.34 | N13: Broken Garlic | O13: =SUMIF(B6:B124,"Broken Garlic",C6:C124) -> 342.5 | T13: 6 | U13: NFS GINGER GARLIC PASTE (500 GRM ) | V13: 26 | W13: =V13/2 -> 13 | X13: 1660
A14: 45783 | B14: Ginger | C14: 54 | E14: 45784 | F14: Broken Garlic | G14: 23.7 | I14: 45785 | J14: Ginger Garlic Paste | K14: 36.31 | T14: 7 | U14: NFS GARLIC PASTE (1 KG) | V14: 28 | W14: =V14 -> 28 | X14: 4480
A15: 45796 | B15: Ginger | C15: 50 | E15: 45784 | F15: Garlic | G15: 44 | I15: 45786 | J15: Ginger Garlic Paste | K15: 17.7 | N15: Pre-Production | O15: Total(Kgs) | P15: Total(Kgs) | T15: 8 | U15: NFS GINGER PASTE ( 1 KG ) | V15: 19 | W15: =V15 -> 19 | X15: 1520
E16: 45785 | F16: Ginger | G16: 28.8 | I16: 45787 | J16: Ginger Garlic Paste | K16: 12.3 | N16: Ginger | O16: =SUMIF(F6:F124,"Ginger",G6:G124) -> 367.9 | P16: =O16 -> 367.9 | V16: =SUM(V8:V15) -> 1171 | W16: =SUM(W8:W15) -> 1099.25
E17: 45786 | F17: Ginger | G17: 17.2 | I17: 45787 | J17: Ginger Garlic Paste | K17: 21 | N17: Garlic | O17: =SUMIF(F6:F126,"Garlic",G6:G126) -> 299 | P17: =SUM(O17:O18) -> 642.4
E18: 45787 | F18: Ginger | G18: 15 | I18: 45787 | J18: Ginger Garlic Paste | K18: 10 | N18: Broken Garlic | O18: =SUMIF(F6:F126,"Broken Garlic",G6:G126) -> 343.4 | X18: =SUM(X8:X17) -> 133760
A19: 45787 | B19: Ginger | C19: 54 | E19: 45785 | F19: Broken Garlic | G19: 38.1 | I19: 45789 | J19: Ginger Garlic Paste | K19: 22.67
A20: 45791 | B20: Ginger | C20: 50 | E20: 45789 | F20: Ginger | G20: 20 | J20: Ginger Garlic Paste | K20: 10
A21: 45791 | B21: Broken Garlic | C21: 197 | E21: 45786 | F21: Broken Garlic | G21: 40.2 | J21: Ginger Garlic Paste | K21: 20 | N21: Post-Production | O21: Total(Kgs)
A22: 45791 | B22: Garlic | C22: 388 | E22: 45787 | F22: Broken Garlic | G22: 40.5 | I22: 45790 | J22: Garlic Peeled | K22: 3 | N22: Ginger Peeled | O22: =SUMIF(J6:J124,"Ginger Peeled",K6:K124) -> 1.5 | T22: S.No. | U22: Item | V22: Qty. | W22: Kgs | X22: Total
A23: 45791 | B23: Broken Garlic | C23: 10.5 | E23: 45789 | F23: Broken Garlic | G23: 39.2 | I23: 45790 | J23: Ginger Garlic Paste | K23: 10 | N23: Garlic Peeled | O23: =SUMIF(J6:J124,"Garlic Peeled",K6:K124) -> 108.5 | T23: 1 | U23: GINGER GARLIC PASTE 1KG | V23: 66 | W23: 845 | X23: =SUM(W23:W25) -> 877.25
A24: 45794 | B24: Broken Garlic | C24: 8.4 | E24: 45792 | F24: Ginger | G24: 12 | I24: 45790 | J24: Ginger Garlic Paste | K24: 15.1 | N24: Ginger Garlic Paste | O24: =SUMIF(J6:J124,"Ginger Garlic Paste",K6:K124) -> 896.21 | T24: 2 | U24: NFS GINGER GARLIC PASTE (250 GMS) | V24: 15 | W24: 19.25
A25: 45794 | B25: Broken Garlic | C25: 7 | E25: 45794 | F25: Ginger | G25: 21.6 | I25: 45790 | J25: Garlic Peeled | K25: 4 | O25: =SUM(O22:O24) -> 1006.21 | T25: 3 | U25: NFS GINGER GARLIC PASTE (500 GRM ) | V25: 9 | W25: 13
A26: 45798 | B26: Broken Garlic | C26: 3.5 | E26: 45794 | F26: Broken Garlic | G26: 31.6 | I26: 45791 | J26: Ginger Garlic Paste | K26: 21.5 | T26: 4 | U26: NFS GARLIC PASTE (1 KG) | V26: 2 | W26: 28 | X26: =W26 -> 28
A27: 45800 | B27: Garlic | C27: 20 | E27: 45796 | F27: Ginger | G27: 15.21 | I27: 45792 | J27: Garlic Peeled | K27: 7 | T27: 5 | U27: NFS GINGER PASTE ( 1 KG ) | V27: 2 | W27: 19 | X27: =W27 -> 19
A28: 45802 | B28: Ginger | C28: 50 | E28: 45796 | F28: Broken Garlic | G28: 20 | I28: 45792 | J28: Ginger Garlic Paste | K28: 23.45 | T28: 6 | U28: NFS PEELED GARLIC ( 500 GRM ) | V28: 2 | W28: 1 | X28: =SUM(W28:W29) -> 171
A29: 45802 | B29: Broken Garlic | C29: 7 | E29: 45797 | F29: Garlic | G29: 39 | I29: 45793 | J29: Ginger Garlic Paste | K29: 16.37 | T29: 7 | U29: NFS PEELED GARLIC 1KG | V29: 26 | W29: 170
A30: 45802 | B30: Broken Garlic | C30: 4.2 | E30: 45798 | F30: Ginger | G30: 10 | I30: 45793 | J30: Garlic Peeled | K30: 6 | T30: 8 | U30: NFS PEELED GINGER | V30: 4 | X30: =W30 -> 0
A31: 45807 | B31: Ginger | C31: 7.5 | E31: 45799 | F31: Broken Garlic | G31: 15 | I31: 45794 | J31: Ginger Garlic Paste | K31: 24.15 | U31: Grand Total | V31: 126 | W31: 1095.25 | X31: =SUM(X23:X30) -> 1095.25
A32: 45807 | B32: Ginger | C32: 25 | E32: 45799 | F32: Broken Garlic | G32: 14 | I32: 45794 | J32: Ginger Garlic Paste | K32: 10
A33: 45807 | B33: Garlic | C33: 4 | E33: 45800 | F33: Ginger | G33: 15 | I33: 45794 | J33: Garlic Peeled | K33: 2
A34: 45808 | B34: Ginger | C34: 50 | E34: 45801 | F34: Ginger | G34: 25 | I34: 45794 | J34: Ginger Garlic Paste | K34: 12.41
E35: 45802 | F35: Ginger | G35: 15 | I35: 45796 | J35: Garlic Peeled | K35: 11
E36: 45800 | F36: Garlic | G36: 38 | I36: 45797 | J36: Ginger Garlic Paste | K36: 28.7
E37: 45801 | F37: Garlic | G37: 20 | I37: 45797 | J37: Garlic Peeled | K37: 28
E38: 45802 | F38: Garlic | G38: 39 | I38: 45798 | J38: Ginger Garlic Paste | K38: 16.8
E39: 45802 | F39: Ginger | G39: 8 | I39: 45798 | J39: Ginger Garlic Paste | K39: 15.7
E40: 45803 | F40: Ginger | G40: 26 | I40: 45798 | J40: Garlic Peeled | K40: 5
E41: 45803 | F41: Broken Garlic | G41: 36 | I41: 45799 | J41: Ginger Garlic Paste | K41: 10.2
...

Sheet June 2025 
E1: Nila Foods & Spices
A2: Daily Stock & Production | C2: 45809
A4: Stock-in | E4: Pre-Production | I4: Post-Production
A5: Date | B5: Material | C5: Weight(Kgs) | E5: Date | F5: Material | G5: Weight(Kgs) | I5: Date | J5: Material | K5: Weight(Kgs)
A6: 45811 | B6: Ginger | C6: 50 | E6: 45809 | F6: Garlic | G6: 38.5 | I6: 45809 | J6: Ginger Garlic Paste | K6: 20
A7: 45813 | B7: Garlic | C7: 452 | E7: 45809 | F7: Ginger | G7: 17.5 | I7: 45809 | J7: Ginger Garlic Paste | K7: 11.15
A8: 45814 | B8: Ginger | C8: 50 | E8: 45810 | F8: Garlic | G8: 79 | I8: 45810 | J8: Ginger Garlic Paste | K8: 26.5 | N8: Available Stock | O8: Total(Kgs)
A9: 45817 | B9: Ginger | C9: 50 | E9: 45812 | F9: Ginger | G9: 23.2 | I9: 45811 | J9: Ginger Garlic Paste | K9: 23.23 | N9: OS - Garlic | O9: =SUMIF(B6:B124,"Os - Ginger",C6:C124) -> 0
A10: 45822 | B10: Ginger | C10: 50 | E10: 45813 | F10: Ginger | G10: 13 | I10: 45811 | J10: Garlic Peeled | K10: 14 | N10: OS - Ginger | O10: =SUMIF(B6:B124,"Os - Garlic",C6:C124) -> 0
A11: 45829 | B11: Ginger | C11: 50 | E11: 45813 | F11: Garlic | G11: 75 | I11: 45812 | J11: Ginger Garlic Paste | K11: 26 | N11: Ginger | O11: =SUMIF(B6:B124,"Ginger",C6:C124) -> 350
A12: 45828 | B12: Garlic | C12: 19 | E12: 45814 | F12: Ginger | G12: 21.9 | I12: 45813 | J12: Ginger Garlic Paste | K12: 19.22 | N12: Garlic | O12: =SUMIF(B6:B124,"Garlic",C6:C124) -> 1381
A13: 45829 | B13: Garlic | C13: 189 | E13: 45815 | F13: Ginger | G13: 26 | I13: 45813 | J13: Garlic Peeled | K13: 26 | N13: Broken Garlic | O13: =SUMIF(B6:B124,"Broken Garlic",C6:C124) -> 0
A14: 45832 | B14: Ginger | C14: 50 | E14: 45815 | F14: Garlic | G14: 38 | I14: 45814 | J14: Ginger Garlic Paste | K14: 10
A15: 45832 | B15: Garlic | C15: 721 | E15: 45817 | F15: Ginger | G15: 17 | I15: 45814 | J15: Ginger Garlic Paste | K15: 20.4 | N15: Pre-Production | O15: Total(Kgs) | P15: Total(Kgs)
A16: 45836 | B16: Ginger | C16: 50 | E16: 45817 | F16: Garlic | G16: 38 | I16: 45814 | J16: Ginger Garlic Paste | K16: 10.13 | N16: Ginger | O16: =SUMIF(F6:F124,"Ginger",G6:G124) -> 373.05 | P16: =O16 -> 373.05
E17: 45818 | F17: Ginger | G17: 14.25 | I17: 45814 | J17: Ginger Garlic Paste | K17: 11 | N17: Garlic | O17: =SUMIF(F6:F126,"Garlic",G6:G126) -> 819.4 | P17: =SUM(O17:O18) -> 858.4
E18: 45820 | F18: Ginger | G18: 8.4 | I18: 45814 | J18: Ginger Garlic Paste | K18: 10.9 | N18: Broken Garlic | O18: =SUMIF(F6:F126,"Broken Garlic",G6:G126) -> 39
E19: 45821 | F19: Garlic | G19: 76 | I19: 45815 | J19: Ginger Garlic Paste | K19: 14.78
E20: 45822 | F20: Ginger | G20: 13.8 | I20: 45815 | J20: Ginger Garlic Paste | K20: 13.6
E21: 45822 | F21: Ginger | G21: 16 | I21: 45816 | J21: Ginger Garlic Paste | K21: 14.35 | N21: Post-Production | O21: Total(Kgs) | P21: Total(Kgs)
E22: 45823 | F22: Ginger | G22: 43 | I22: 45817 | J22: Ginger Garlic Paste | K22: 22.6 | N22: Ginger Peeled | O22: =SUMIF(J6:J124,"Ginger Peeled",K6:K124) -> 0.5 | P22: =SUM(O22:O24) -> 1005.01
F23: Garlic | G23: 76 | I23: 45817 | J23: Ginger Garlic Paste | K23: 10 | N23: Garlic Peeled | O23: =SUMIF(J6:J124,"Garlic Peeled",K6:K124) -> 186.5
F24: Ginger | G24: 39 | I24: 45818 | J24: Garlic Peeled | K24: 8 | N24: Ginger Garlic Paste | O24: =SUMIF(J6:J124,"Ginger Garlic Paste",K6:K124) -> 818.01
E25: 45825 | F25: Garlic | G25: 89 | I25: 45819 | J25: Ginger Garlic Paste | K25: 46.6
F26: Ginger | G26: 32 | I26: 45821 | J26: Ginger Garlic Paste | K26: 16
E27: 45829 | F27: Garlic | G27: 38 | I27: 45821 | J27: Garlic Peeled | K27: 16
F28: Garlic | G28: 19 | I28: 45822 | J28: Ginger Garlic Paste | K28: 65
E29: 45830 | F29: Ginger | G29: 6 | I29: 45822 | J29: Garlic Peeled | K29: 9
E30: 45831 | F30: Garlic | G30: 77 | I30: 45823 | J30: Ginger Garlic Paste | K30: 8.75
F31: Ginger | G31: 15 | I31: 45823 | J31: Ginger Garlic Paste | K31: 79
E32: 45832 | F32: Garlic | G32: 39 | I32: 45823 | J32: Garlic Peeled | K32: 27
F33: Ginger | G33: 16 | I33: 45824 | J33: Ginger Garlic Paste | K33: 15
E34: 45834 | F34: Garlic | G34: 48 | I34: 45828 | J34: Garlic Peeled | K34: 20
E35: 45834 | F35: Ginger | G35: 16.5 | I35: 45828 | J35: Ginger Peeled | K35: 0.5
E36: 45835 | F36: Ginger | G36: 14 | I36: 45828 | J36: Garlic Peeled | K36: 0.5
E37: 45836 | F37: Ginger | G37: 19.5 | I37: 45828 | J37: Ginger Garlic Paste | K37: 3
E38: 45836 | F38: Garlic | G38: 31 | I38: 45828 | J38: Ginger Garlic Paste | K38: 53
E39: 45838 | F39: Ginger | G39: 1 | I39: 45829 | J39: Garlic Peeled | K39: 11
E40: 45838 | F40: Broken Garlic | G40: 31 | I40: 45829 | J40: Ginger Garlic Paste | K40: 69
E41: 45838 | F41: Broken Garlic | G41: 8 | I41: 45831 | J41: Ginger Garlic Paste | K41: 42
...

Sheet June 2025111
E1: Nila Foods & Spices
A2: Daily Stock & Production | C2: 45778
A4: Stock-in | E4: Pre-Production | I4: Post-Production
A5: Date | B5: Material | C5: Weight(Kgs) | E5: Date | F5: Material | G5: Weight(Kgs) | I5: Date | J5: Material | K5: Weight(Kgs)
A6: 45811 | B6: Ginger | C6: 50 | E6: 45809 | F6: Garlic | G6: 38.5 | I6: 45809 | J6: Ginger Garlic Paste | K6: 20
B7: Garlic | C7: 452 | E7: 45809 | F7: Ginger | G7: 17.5 | I7: 45809 | J7: Ginger Garlic Paste | K7: 11.15
E8: 45810 | F8: Garlic | G8: 79 | I8: 45810 | J8: Ginger Garlic Paste | K8: 26.5 | N8: Available Stock | O8: Total(Kgs)
E9: 45812 | F9: Ginger | G9: 23.2 | I9: 45811 | J9: Ginger Garlic Paste | K9: 23.23 | N9: OS - Garlic | O9: =SUMIF(B6:B124,"Os - Ginger",C6:C124) -> 0
E10: 45813 | F10: Ginger | G10: 13 | I10: 45811 | J10: Garlic Peeled | K10: 14 | N10: OS - Ginger | O10: =SUMIF(B6:B124,"Os - Garlic",C6:C124) -> 0
E11: 45813 | F11: Garlic | G11: 75 | I11: 45812 | J11: Ginger Garlic Paste | K11: 26 | N11: Ginger | O11: =SUMIF(B6:B124,"Ginger",C6:C124) -> 50
I12: 45813 | J12: Ginger Garlic Paste | K12: 19.22 | N12: Garlic | O12: =SUMIF(B6:B124,"Garlic",C6:C124) -> 452
I13: 45813 | J13: Garlic Peeled | K13: 26 | N13: Broken Garlic | O13: =SUMIF(B6:B124,"Broken Garlic",C6:C124) -> 0
N15: Pre-Production | O15: Total(Kgs)
N16: Ginger | O16: =SUMIF(F6:F124,"Ginger",G6:G124) -> 53.7
N17: Garlic | O17: =SUMIF(F8:F126,"Garlic",G8:G126) -> 154
N18: Broken Garlic | O18: =SUMIF(F8:F126,"Broken Garlic",G8:G126) -> 0
N21: Post-Production | O21: Total(Kgs)
N22: Ginger Peeled | O22: =SUMIF(J6:J124,"Ginger Peeled",K6:K124) -> 0
N23: Garlic Peeled | O23: =SUMIF(J6:J124,"Garlic Peeled",K6:K124) -> 40
N24: Ginger Garlic Paste | O24: =SUMIF(J6:J124,"Ginger Garlic Paste",K6:K124) -> 126.1

Sheet July 2025
E1: Nila Foods & Spices
A2: Daily Stock & Production | C2: 45839
A4: Stock-in | E4: Pre-Production | I4: Post-Production
A5: Date | B5: Material | C5: Weight(Kgs) | E5: Date | F5: Material | G5: Weight(Kgs) | I5: Date | J5: Material | K5: Weight(Kgs)
A6: 45839 | B6: OS - Ginger | C6: 35.42 | E6: 45839 | F6: Broken Garlic | G6: 51 | I6: 45839 | J6: Ginger Garlic Paste | K6: 45.3
A7: 45839 | B7: OS - Garlic | C7: 660.91 | E7: 45839 | F7: Ginger | G7: 17.5 | I7: 45839 | J7: Garlic Peeled | K7: 8
A8: 45839 | B8: OS - Ginger Garlic Paste | C8: 37.5 | E8: 45839 | F8: Garlic | G8: 48.37 | I8: 45840 | J8: Ginger Garlic Paste | K8: 27 | N8: Overall Stock | O8: Total(Kgs) | P8: Total(kgs) | R8: Overall Processed
A9: 45839 | B9: OS - Garlic Peeled | C9: 10.5 | E9: 45840 | F9: Ginger | G9: 11.4 | I9: 45840 | J9: Garlic Peeled | K9: 2 | N9: OS - Ginger | O9: =SUMIF(B6:B124,"OS - Ginger",C6:C124) -> 35.42 | P9: =SUM(O9:O10) -> 553.42 | R9: =P9 -> 553.42
A10: 45839 | B10: OS - Ginger Peeled | E10: 45840 | F10: Broken Garlic | G10: 8 | I10: 45841 | J10: Garlic Peeled | K10: 11 | N10: Ginger Purchase | O10: =SUMIF(B6:B124,"Ginger",C6:C124) -> 518
A11: 45839 | B11: OS - Broken Garlic | C11: 55.5 | E11: 45842 | F11: Ginger | G11: 17.5 | I11: 45842 | J11: Ginger Garlic Paste | K11: 49.5 | N11: OS - Garlic | O11: =SUMIF(B6:B124,"OS - Garlic",C6:C124) -> 660.91 | P11: =SUM(O11:O12) -> 989.78 | Q11: =SUM(P11:P14) -> 1045.28 | R11: =O11 -> 660.91 | S11: =SUM(R11:R15) -> 983.78
A12: 45839 | B12: Broken Garlic | E12: 45842 | F12: Garlic | G12: 95.43 | I12: 45843 | J12: Garlic Peeled | K12: 11 | N12: Garlic Purchase | O12: =SUMIF(B6:B124,"Garlic",C6:C124) -> 328.87 | R12: =O12-'Aug 2025'!C8 -> 256.87
A13: 45840 | B13: Ginger | C13: 54 | E13: 45843 | F13: Ginger | G13: 14 | I13: 45843 | J13: Ginger Garlic Paste | K13: 35 | N13: OS - Broken Garlic | O13: =SUMIF(B6:B124,"OS - Broken Garlic",C6:C124) -> 55.5 | P13: =SUM(O13:O14) -> 55.5 | R13: =P13 -> 55.5
A14: 45846 | B14: Garlic | C14: 20 | E14: 45845 | F14: Ginger | G14: 0.6 | I14: 45845 | J14: Garlic Peeled | K14: 9 | N14: Broken Garlic | O14: =SUMIF(B6:B124,"Broken Garlic",C6:C124) -> 0
A15: 45849 | B15: Garlic | C15: 44 | E15: 45846 | F15: Ginger | G15: 14.8 | I15: 45845 | J15: Ginger Peeled | K15: 0.5 | N15: OS - Garlic Peeled | O15: =SUMIF(B6:B124,"OS - Garlic Peeled",C6:C124) -> 10.5 | P15: =O15 -> 10.5 | R15: =P15 -> 10.5
A16: 45849 | B16: Ginger | C16: 100 | E16: 45846 | F16: Garlic | G16: 20 | I16: 45846 | J16: Garlic Peeled | K16: 7 | N16: OS - Ginger Peeled | O16: =SUMIF(B6:B124,"OS - Ginger Peeled",C6:C124) -> 0
A17: 45850 | B17: Garlic | C17: 10 | E17: 45848 | F17: Garlic | G17: 48.35 | I17: 45846 | J17: Ginger Garlic Paste | K17: 33.3 | N17: OS - Ginger Garlic Paste | O17: =SUMIF(B6:B124,"OS - Ginger Garlic Paste",C6:C124) -> 37.5
A18: 45850 | B18: Ginger | C18: 50 | E18: 45848 | F18: Garlic | G18: 47.5 | I18: 45848 | J18: Garlic Peeled | K18: 7 | N18: Ginger Paste | O18: =SUMIF(B6:B124,"OS - Ginger Paste",C6:C124) -> 0
A19: 45852 | B19: Ginger | C19: 50 | E19: 45849 | F19: Garlic | G19: 44 | I19: 45849 | J19: Garlic Peeled | K19: 32 | N19: Garlic Paste | O19: =SUMIF(B6:B124,"OS - Garlic Paste",C6:C124) -> 0
A20: 45853 | B20: Garlic | C20: 10 | E20: 45849 | F20: Ginger | G20: 50 | I20: 45849 | J20: Ginger Garlic Paste | K20: 86
A21: 45857 | B21: Garlic | C21: 10 | E21: 45850 | F21: Ginger | G21: 50 | I21: 45850 | J21: Ginger Garlic Paste | K21: 35 | N21: Pre-Production | O21: Total(Kgs) | P21: Total(Kgs)
A22: 45857 | B22: Ginger | C22: 50 | E22: 45850 | F22: Garlic | G22: 30 | I22: 45850 | J22: Ginger Garlic Paste | K22: 65 | N22: Ginger | O22: =SUMIF(F6:F124,"Ginger",G6:G124) -> 519.77 | P22: =O22 -> 519.77
A23: 45859 | B23: Ginger | C23: 50 | E23: 45850 | F23: Garlic | G23: 47.47 | I23: 45850 | J23: Garlic Peeled | K23: 9 | N23: Garlic | O23: =SUMIF(F6:F126,"Garlic",G6:G126) -> 789.82 | P23: =SUM(O23:O24) -> 848.82
A24: 45859 | B24: Garlic | C24: 10 | E24: 45850 | F24: Garlic | G24: 47.3 | I24: 45850 | J24: Ginger Garlic Paste | K24: 46.5 | N24: Broken Garlic | O24: =SUMIF(F6:F126,"Broken Garlic",G6:G126) -> 59
A25: 45861 | B25: Garlic | C25: 37.11 | E25: 45850 | F25: Garlic | G25: 47.9 | I25: 45851 | J25: Ginger Garlic Paste | K25: 56.5
A26: 45861 | B26: Garlic | C26: 37.43 | E26: 45850 | F26: Ginger | G26: 19 | I26: 45851 | J26: Garlic Peeled | K26: 5
A27: 45861 | B27: Garlic | C27: 37.7 | E27: 45851 | F27: Ginger | G27: 25.7 | I27: 45852 | J27: Garlic Peeled | K27: 5 | N27: Post-Production | O27: Total(Kgs) | P27: Total Inclu. OS(Kgs)
A28: 45861 | B28: Garlic | C28: 37.52 | E28: 45852 | F28: Ginger | G28: 16.5 | I28: 45852 | J28: Ginger Garlic Paste | K28: 59.5 | N28: Ginger Peeled | O28: =SUMIF(J6:J124,"Ginger Peeled",K6:K124) -> 0.5 | P28: =SUM(O28,O16) -> 0.5
A29: 45861 | B29: Garlic | C29: 37.51 | E29: 45852 | F29: Garlic | G29: 48.23 | I29: 45853 | J29: Garlic Peeled | K29: 12 | N29: Garlic Peeled | O29: =SUMIF(J6:J124,"Garlic Peeled",K6:K124) -> 175 | P29: =SUM(O29,O15) -> 185.5
A30: 45861 | B30: Garlic | C30: 37.6 | E30: 45853 | F30: Garlic | G30: 48.43 | I30: 45855 | J30: Ginger Garlic Paste | K30: 49 | N30: Ginger Garlic Paste | O30: =SUMIF(J6:J124,"Ginger Garlic Paste",K6:K124) -> 1146.8 | P30: =SUM(O30,O17) -> 1184.3
A31: 45862 | B31: Ginger | C31: 53.1 | E31: 45855 | F31: Ginger | G31: 29.85 | I31: 45855 | J31: Ginger Garlic Paste | K31: 12 | N31: Ginger Paste | O31: =SUMIF(J6:J124,"Ginger Paste",K6:K124) -> 2 | P31: =SUM(O31,O18) -> 2
A32: 45865 | B32: Ginger | C32: 56.7 | E32: 45857 | F32: Ginger | G32: 57.8 | I32: 45855 | J32: Garlic Peeled | K32: 7 | N32: Garlic Paste | O32: =SUMIF(J6:J124,"Garlic Paste",K6:K124) -> 0 | P32: =SUM(O32,O19) -> 0
A33: 45867 | B33: Ginger | C33: 54.2 | E33: 45859 | F33: Garlic | G33: 47.8 | I33: 45857 | J33: Ginger Garlic Paste | K33: 122.2
E34: 45859 | F34: Ginger | G34: 22.6 | I34: 45857 | J34: Garlic Peeled | K34: 9 | N34: Available Stock | O34: Total(Kgs)
E35: 45860 | F35: Garlic | G35: 47.8 | I35: 45859 | J35: Ginger Garlic Paste | K35: 59 | N35: Gigner | O35: =P9-P22 -> 33.65
E36: 45860 | F36: Garlic | G36: 46.7 | I36: 45860 | J36: Garlic Peeled | K36: 7 | N36: Garlic | O36: =Q11-P23 -> 196.46
E37: 45860 | F37: Ginger | G37: 19.5 | I37: 45860 | J37: Ginger Garlic Paste | K37: 56.5
E38: 45863 | F38: Ginger | G38: 26 | I38: 45861 | J38: Garlic Peeled | K38: 7
E39: 45864 | F39: Garlic | G39: 37.11 | I39: 45863 | J39: Ginger Garlic Paste | K39: 61
E40: 45864 | F40: Garlic | G40: 37.43 | I40: 45863 | J40: Garlic Peeled | K40: 5
E41: 45864 | F41: Ginger | G41: 33.8 | I41: 45864 | J41: Ginger Garlic Paste | K41: 68
...

Sheet July 2025 (2)
E1: Nila Foods & Spices
A2: Daily Stock & Production | C2: 45839
A4: Stock-in | E4: Pre-Production | I4: Post-Production
A5: Date | B5: Material | C5: Weight(Kgs) | E5: Date | F5: Material | G5: Weight(Kgs) | I5: Date | J5: Material | K5: Weight(Kgs)
A6: 45839 | B6: OS - Ginger | C6: 35.42 | E6: 45839 | F6: Broken Garlic | G6: 51 | I6: 45839 | J6: Ginger Garlic Paste | K6: 45.3
A7: 45839 | B7: OS - Garlic | C7: 660.91 | E7: 45839 | F7: Ginger | G7: 17.5 | I7: 45839 | J7: Garlic Peeled | K7: 8
A8: 45839 | B8: OS - Ginger Garlic Paste | C8: 37.5 | E8: 45839 | F8: Garlic | G8: 38.37 | I8: 45840 | J8: Ginger Garlic Paste | K8: 27 | N8: Overall Stock | O8: Total(Kgs) | P8: Total(kgs)
A9: 45839 | B9: OS - Garlic Peeled | C9: 10.5 | E9: 45840 | F9: Ginger | G9: 11.4 | I9: 45840 | J9: Garlic Peeled | K9: 2 | N9: OS - Ginger | O9: =SUMIF(B6:B124,"OS - Ginger",C6:C124) -> 35.42 | P9: =SUM(O9:O10) -> 339.42
A10: 45839 | B10: OS - Ginger Peeled | E10: 45840 | F10: Broken Garlic | G10: 8 | I10: 45841 | J10: Garlic Peeled | K10: 11 | N10: Ginger | O10: =SUMIF(B6:B124,"Ginger",C6:C124) -> 304
A11: 45839 | B11: OS - Broken Garlic | C11: 55.5 | E11: 45842 | F11: Ginger | G11: 17.5 | I11: 45842 | J11: Ginger Garlic Paste | K11: 49.5 | N11: OS - Garlic | O11: =SUMIF(B6:B124,"OS - Garlic",C6:C124) -> 660.91 | P11: =SUM(O11:O12) -> 754.91 | Q11: =SUM(P11:P14) -> 810.41
A12: 45839 | B12: Broken Garlic | E12: 45842 | F12: Garlic | G12: 95.43 | I12: 45843 | J12: Garlic Peeled | K12: 11 | N12: Garlic | O12: =SUMIF(B6:B124,"Garlic",C6:C124) -> 94
A13: 45840 | B13: Ginger | C13: 54 | E13: 45843 | F13: Ginger | G13: 14 | I13: 45843 | J13: Ginger Garlic Paste | K13: 35 | N13: OS - Broken Garlic | O13: =SUMIF(B6:B124,"OS - Broken Garlic",C6:C124) -> 55.5 | P13: =SUM(O13:O14) -> 55.5
A14: 45846 | B14: Garlic | C14: 20 | E14: 45845 | F14: Ginger | G14: 0.6 | I14: 45845 | J14: Garlic Peeled | K14: 9 | N14: Broken Garlic | O14: =SUMIF(B6:B124,"Broken Garlic",C6:C124) -> 0
A15: 45849 | B15: Garlic | C15: 44 | E15: 45846 | F15: Ginger | G15: 14.8 | I15: 45845 | J15: Ginger Peeled | K15: 0.5 | N15: OS - Garlic Peeled | O15: =SUMIF(B6:B124,"OS - Garlic Peeled",C6:C124) -> 10.5
A16: 45849 | B16: Ginger | C16: 100 | E16: 45846 | F16: Garlic | G16: 20 | I16: 45846 | J16: Garlic Peeled | K16: 7 | N16: OS - Ginger Peeled | O16: =SUMIF(B6:B124,"OS - Ginger Peeled",C6:C124) -> 0
A17: 45850 | B17: Garlic | C17: 10 | E17: 45848 | F17: Garlic | G17: 48.35 | I17: 45846 | J17: Ginger Garlic Paste | K17: 33.3 | N17: OS - Ginger Garlic Paste | O17: =SUMIF(B6:B124,"OS - Ginger Garlic Paste",C6:C124) -> 37.5
A18: 45850 | B18: Ginger | C18: 50 | E18: 45848 | F18: Garlic | G18: 47.5 | I18: 45848 | J18: Garlic Peeled | K18: 7
A19: 45852 | B19: Ginger | C19: 50 | E19: 45849 | F19: Garlic | G19: 44 | I19: 45849 | J19: Garlic Peeled | K19: 32 | N19: Pre-Production | O19: Total(Kgs) | P19: Total(Kgs)
A20: 45853 | B20: Garlic | C20: 10 | E20: 45849 | F20: Ginger | G20: 50 | I20: 45849 | J20: Ginger Garlic Paste | K20: 86 | N20: Ginger | O20: =SUMIF(F6:F124,"Ginger",G6:G124) -> 324.65 | P20: =O20 -> 324.65
A21: 45857 | B21: Garlic | C21: 10 | E21: 45850 | F21: Ginger | G21: 50 | I21: 45850 | J21: Ginger Garlic Paste | K21: 35 | N21: Garlic | O21: =SUMIF(F6:F126,"Garlic",G6:G126) -> 540.98 | P21: =SUM(O21:O22) -> 599.98
A22: 45857 | B22: Ginger | C22: 50 | E22: 45850 | F22: Garlic | G22: 10 | I22: 45850 | J22: Ginger Garlic Paste | K22: 65 | N22: Broken Garlic | O22: =SUMIF(F6:F126,"Broken Garlic",G6:G126) -> 59
E23: 45850 | F23: Garlic | G23: 47.47 | I23: 45850 | J23: Garlic Peeled | K23: 9
E24: 45850 | F24: Garlic | G24: 47.3 | I24: 45850 | J24: Ginger Garlic Paste | K24: 46.5
E25: 45850 | F25: Garlic | G25: 47.9 | I25: 45851 | J25: Ginger Garlic Paste | K25: 56.5 | N25: Post-Production | O25: Total(Kgs)
E26: 45850 | F26: Ginger | G26: 19 | I26: 45851 | J26: Garlic Peeled | K26: 5 | N26: Ginger Peeled | O26: =SUMIF(J6:J124,"Ginger Peeled",K6:K124) -> 0.5
E27: 45851 | F27: Ginger | G27: 25.7 | I27: 45852 | J27: Garlic Peeled | K27: 5 | N27: Garlic Peeled | O27: =SUMIF(J6:J124,"Garlic Peeled",K6:K124) -> 134
E28: 45852 | F28: Ginger | G28: 16.5 | I28: 45852 | J28: Ginger Garlic Paste | K28: 59.5 | N28: Ginger Garlic Paste | O28: =SUMIF(J6:J124,"Ginger Garlic Paste",K6:K124) -> 721.8
E29: 45852 | F29: Garlic | G29: 47.23 | I29: 45853 | J29: Garlic Peeled | K29: 12
E30: 45853 | F30: Garlic | G30: 47.43 | I30: 45855 | J30: Ginger Garlic Paste | K30: 49
E31: 45855 | F31: Ginger | G31: 29.85 | I31: 45855 | J31: Ginger Garlic Paste | K31: 12 | N31: Available Stock | O31: Total(Kgs)
E32: 45857 | F32: Ginger | G32: 57.8 | I32: 45855 | J32: Garlic Peeled | K32: 7 | N32: Gigner | O32: =P9-P20 -> 14.77
I33: 45857 | J33: Ginger Garlic Paste | K33: 122.2 | N33: Garlic | O33: =Q11-P21 -> 210.43
I34: 45857 | J34: Garlic Peeled | K34: 9

Sheet Aug 2025
E1: Nila Foods & Spices
A2: Daily Stock & Production | C2: 45870
A4: Stock-in | E4: Pre-Production | I4: Post-Production
A5: Date | B5: Material | C5: Weight(Kgs) | E5: Date | F5: Material | G5: Weight(Kgs) | I5: Date | J5: Material | K5: Weight(Kgs) | N5: OS - Opening Stock
A6: 45870 | B6: OS - Ginger | E6: 45871 | F6: Ginger | G6: 15.7 | I6: 45872 | J6: Ginger Garlic Paste | K6: 35
A7: 45870 | B7: OS - Garlic | C7: 75.3 | E7: 45872 | F7: Garlic | G7: 37.6 | I7: 45872 | J7: Ginger Garlic Paste | K7: 7
A8: 45870 | B8: OS - Ginger Garlic Paste | C8: 72 | E8: 45873 | F8: Ginger | G8: 7 | I8: 45872 | J8: Ginger Garlic Paste | K8: 7 | N8: Overall Stock | O8: Total(Kgs) | P8: Total(kgs)
A9: 45870 | B9: OS - Garlic Peeled | C9: 12 | E9: 45873 | F9: Garlic | G9: 37.6 | I9: 45873 | J9: Ginger Garlic Paste | K9: 49 | N9: OS - Ginger | O9: =SUMIF(B6:B124,"OS - Ginger",C6:C124) -> 0 | P9: =SUM(O9:O10) -> 627.37
A10: 45870 | B10: OS - Ginger Peeled | E10: 45873 | F10: Ginger | G10: 19.3 | I10: 45873 | J10: Garlic Peeled | K10: 5 | N10: Ginger | O10: =SUMIF(B6:B124,"Ginger",C6:C124) -> 627.37
A11: 45870 | B11: OS - Broken Garlic | C11: 19.5 | E11: 45873 | F11: Ginger | G11: 3.7 | I11: 45875 | J11: Ginger Garlic Paste | K11: 43 | N11: OS - Garlic | O11: =SUMIF(B6:B124,"OS - Garlic",C6:C124) -> 75.3 | P11: =SUM(O11:O12) -> 913.26 | Q11: =SUM(P11:P14) -> 932.76
A12: 45870 | B12: Broken Garlic | E12: 45875 | F12: Ginger | G12: 32.5 | I12: 45876 | J12: Ginger Garlic Paste | K12: 59.5 | N12: Garlic | O12: =SUMIF(B6:B124,"Garlic",C6:C124) -> 837.96
A13: 45870 | B13: OS - Ginger Paste | E13: 45876 | F13: Ginger | G13: 27 | I13: 45877 | J13: Ginger Garlic Paste | K13: 64.5 | N13: OS - Broken Garlic | O13: =SUMIF(B6:B124,"OS - Broken Garlic",C6:C124) -> 19.5 | P13: =SUM(O13:O14) -> 19.5
A14: 45870 | B14: OS - Garlic Paste | E14: 45876 | F14: Garlic | G14: 25.8 | I14: 45878 | J14: Ginger Garlic Paste | K14: 84 | N14: Broken Garlic | O14: =SUMIF(B6:B124,"Broken Garlic",C6:C124) -> 0
A15: 45871 | B15: Ginger | C15: 56.45 | E15: 45876 | F15: Garlic | G15: 3.5 | I15: 45879 | J15: Ginger Garlic Paste | K15: 51 | N15: OS - Garlic Peeled | O15: =SUMIF(B6:B124,"OS - Garlic Peeled",C6:C124) -> 12 | P15: =O15 -> 12
A16: 45875 | B16: Ginger | C16: 56.67 | E16: 45877 | F16: Garlic | G16: 33.2 | I16: 45881 | J16: Ginger Garlic Paste | K16: 80 | N16: OS - Ginger Peeled | O16: =SUMIF(B6:B124,"OS - Ginger Peeled",C6:C124) -> 0
A17: 45875 | B17: Garlic | C17: 40.2 | E17: 45878 | F17: Garlic | G17: 39.49 | I17: 45883 | J17: Ginger Garlic Paste | K17: 42.36 | N17: OS - Ginger Garlic Paste | O17: =SUMIF(B6:B124,"OS - Ginger Garlic Paste",C6:C124) -> 72
A18: 45875 | B18: Garlic | C18: 25.89 | E18: 45878 | F18: Ginger | G18: 32.5 | I18: 45883 | J18: Garlic Peeled | K18: 10 | N18: Ginger Paste | O18: =SUMIF(B6:B124,"OS - Ginger Paste",C6:C124) -> 0
A19: 45877 | B19: Ginger | C19: 3.5 | E19: 45878 | F19: Ginger | G19: 8.6 | I19: 45884 | J19: Ginger Garlic Paste | K19: 53.6 | N19: Garlic Paste | O19: =SUMIF(B6:B124,"OS - Garlic Paste",C6:C124) -> 0
A20: 45877 | B20: Garlic | C20: 3.5 | E20: 45879 | F20: Garlic | G20: 39.5 | I20: 45885 | J20: Ginger Garlic Paste | K20: 53.7
A21: 45877 | B21: Ginger | C21: 56.8 | E21: 45879 | F21: Ginger | G21: 29.5 | I21: 45887 | J21: Ginger Garlic Paste | K21: 59.1 | N21: Pre-Production | O21: Total(Kgs) | P21: Total(Kgs)
A22: 45877 | B22: Ginger | C22: 56.88 | E22: 45880 | F22: Garlic | G22: 39.46 | I22: 45887 | J22: Garlic Peeled | K22: 12 | N22: Ginger | O22: =SUMIF(F6:F124,"Ginger",G6:G124) -> 492.72 | P22: =O22 -> 492.72
A23: 45877 | B23: Garlic | C23: 33.5 | E23: 45881 | F23: Ginger | G23: 32.5 | I23: 45889 | J23: Garlic Peeled | K23: 17.5 | N23: Garlic | O23: =SUMIF(F6:F126,"Garlic",G6:G126) -> 829.48 | P23: =SUM(O23:O24) -> 829.48
A24: 45877 | B24: Garlic | C24: 39.45 | E24: 45881 | F24: Garlic | G24: 13.9 | I24: 45890 | J24: Ginger Garlic Paste | K24: 41.5 | N24: Broken Garlic | O24: =SUMIF(F6:F126,"Broken Garlic",G6:G126) -> 0
A25: 45877 | B25: Garlic | C25: 39.54 | E25: 45882 | F25: Garlic | G25: 39.54 | I25: 45892 | J25: Ginger Garlic Paste | K25: 104
A26: 45877 | B26: Garlic | C26: 39.5 | E26: 45883 | F26: Ginger | G26: 18.5 | I26: 45893 | J26: Ginger Garlic Paste | K26: 38
A27: 45877 | B27: Garlic | C27: 39.46 | E27: 45883 | F27: Garlic | G27: 20 | I27: 45893 | J27: Garlic Peeled | K27: 25 | N27: Post-Production | O27: Total(Kgs) | P27: Total Inclu. OS(Kgs)
A28: 45877 | B28: Garlic | C28: 39.49 | E28: 45884 | F28: Ginger | G28: 24 | I28: 45895 | J28: Ginger Garlic Paste | K28: 79.71 | N28: Ginger Peeled | O28: =SUMIF(J6:J124,"Ginger Peeled",K6:K124) -> 3 | P28: =SUM(O28,O16) -> 3
A29: 45881 | B29: Ginger | C29: 56.83 | E29: 45884 | F29: Ginger | G29: 7.9 | I29: 45895 | J29: Ginger Peeled | K29: 1 | N29: Garlic Peeled | O29: =SUMIF(J6:J124,"Garlic Peeled",K6:K124) -> 94.5 | P29: =SUM(O29,O15) -> 106.5
A30: 45881 | B30: Garlic | C30: 36.98 | E30: 45885 | F30: Garlic | G30: 39.54 | I30: 45896 | J30: Garlic Peeled | K30: 14 | N30: Ginger Garlic Paste | O30: =SUMIF(J6:J124,"Ginger Garlic Paste",K6:K124) -> 1200.27 | P30: =SUM(O30,O17) -> 1272.27
A31: 45881 | B31: Garlic | C31: 36.4 | E31: 45885 | F31: Ginger | G31: 24.3 | I31: 45897 | J31: Garlic Peeled | K31: 11 | N31: Ginger Paste | O31: =SUMIF(J6:J124,"Ginger Paste",K6:K124) -> 0 | P31: =SUM(O31,O18) -> 0
A32: 45882 | B32: Garlic | C32: 36.7 | E32: 45887 | F32: Garlic | G32: 36.7 | I32: 45897 | J32: Ginger Garlic Paste | K32: 34 | N32: Garlic Paste | O32: =SUMIF(J6:J124,"Garlic Paste",K6:K124) -> 0 | P32: =SUM(O32,O19) -> 0
A33: 45882 | B33: Garlic | C33: 35.8 | E33: 45887 | F33: Ginger | G33: 30.1 | I33: 45898 | J33: Ginger Garlic Paste | K33: 64
A34: 45882 | B34: Garlic | C34: 36.5 | E34: 45889 | F34: Garlic | G34: 36.98 | I34: 45898 | J34: Ginger Peeled | K34: 2 | N34: Available Stock | O34: Total(Kgs)
A35: 45884 | B35: Ginger | C35: 56.9 | E35: 45890 | F35: Ginger | G35: 13.2 | I35: 45899 | J35: Ginger Garlic Paste | K35: 15.1 | N35: Gigner | O35: =P9-P22 -> 134.65
A36: 45887 | B36: Ginger | C36: 56.8 | E36: 45891 | F36: Garlic | G36: 39.5 | I36: 45899 | J36: Ginger Garlic Paste | K36: 35.5 | L36: . | N36: Garlic | O36: =Q11-P23 -> 103.28
A37: 45891 | B37: Garlic | C37: 39.32 | E37: 45891 | F37: Garlic | G37: 39.57 | I37: 45900 | J37: Ginger Garlic Paste | K37: 99.7
A38: 45891 | B38: Garlic | C38: 39.37 | E38: 45892 | F38: Ginger | G38: 30.5
A39: 45891 | B39: Garlic | C39: 39.5 | E39: 45893 | F39: Garlic | G39: 36.8
A40: 45891 | B40: Garlic | C40: 39.46 | E40: 45893 | F40: Garlic | G40: 39.4
A41: 45891 | B41: Garlic | C41: 39.26 | E41: 45893 | F41: Ginger | G41: 16.82
...

Sheet Sheet1
B6: NUTRITIONAL INFORMATION* Per 100g of the Product (Approx) | D6: Nutritional Information per Serving -10g
B7: Energy | C7: 105 Kcal | D7: 10.5 Kcal
B8: Protein | C8: 2.85 8 | D8: 0.28 8
B9: Fiber | C9: 5.62 8 | D9: 0.56 g
B10: Carbohydrate | C10: 16.3 g | D10: 1.63 g
B11: Total Sugar | C11: NIL | D11: NIL
B12: Total Fat | C12: 3.14 g | D12: 0.31 g
B13: Trans Fat | C13: NIL | D13: NIL
B14: Cholesterol | C14: NIL | D14: NIL
B15: Sodium | C15: 215 mg | D15: 21.5 mg
B16: Calcium | C16: 9 mg | D16: 0.90 mg
B17: Iron | C17: 0.11 mg | D17: 0.01 m8
B18: *Source: NIN-Nutritive Value of Indian Foods

Sheet Sep 2025
E1: Nila Foods & Spices
A2: Daily Stock & Production | C2: 45901
A4: Stock-in | E4: Pre-Production | I4: Post-Production
A5: Date | B5: Material | C5: Weight(Kgs) | E5: Date | F5: Material | G5: Weight(Kgs) | I5: Date | J5: Material | K5: Weight(Kgs) | N5: OS - Opening Stock
A6: 45901 | B6: OS - Ginger | C6: 23.9 | E6: 45902 | F6: Broken Garlic | G6: 56 | I6: 45902 | J6: Ginger Garlic Paste | K6: 74.8
A7: 45901 | B7: OS - Garlic | C7: 116.8 | E7: 45902 | F7: Ginger | G7: 31 | I7: 45903 | J7: Garlic Paste | K7: 16
A8: 45901 | B8: OS - Ginger Garlic Paste | C8: 100 | E8: 45902 | F8: Ginger | G8: 16 | I8: 45903 | J8: Ginger Paste | K8: 16 | N8: Overall Stock | O8: Total(Kgs) | P8: Total(kgs)
A9: 45901 | B9: OS - Garlic Peeled | C9: 12 | E9: 45903 | F9: Garlic | G9: 38.9 | I9: 45903 | J9: Ginger Garlic Paste | K9: 51 | N9: OS - Ginger | O9: =SUMIF(B6:B126,"OS - Ginger",C6:C126) -> 23.9 | P9: =SUM(O9:O10) -> 731.08
A10: 45901 | B10: OS - Ginger Peeled | E10: 45903 | F10: Garlic | G10: 39.17 | I10: 45903 | J10: Ginger Garlic Paste | K10: 50 | N10: Ginger | O10: =SUMIF(B6:B126,"Ginger",C6:C126) -> 707.18
A11: 45901 | B11: OS - Broken Garlic | C11: 56 | E11: 45903 | F11: Ginger | G11: 36.8 | I11: 45903 | J11: Garlic Paste | K11: 5 | N11: OS - Garlic | O11: =SUMIF(B6:B126,"OS - Garlic",C6:C126) -> 116.8 | P11: =SUM(O11:O12) -> 1258.85 | Q11: =SUM(P11:P14) -> 1332.99
A12: 45901 | B12: Broken Garlic | C12: 7.6 | E12: 45903 | F12: Ginger | G12: 32 | I12: 45903 | J12: Ginger Paste | K12: 5 | N12: Garlic Purchase | O12: =SUMIF(B6:B126,"Garlic",C6:C126) -> 1142.05
A13: 45901 | B13: OS - Ginger Paste | E13: 45904 | F13: Garlic | G13: 35 | I13: 45904 | J13: Ginger Garlic Paste | K13: 166.5 | N13: OS - Broken Garlic | O13: =SUMIF(B6:B126,"OS - Broken Garlic",C6:C126) -> 56 | P13: =SUM(O13:O14) -> 74.14
A14: 45901 | B14: OS - Garlic Paste | E14: 45904 | F14: Garlic | G14: 38.8 | I14: 45905 | J14: Ginger Garlic Paste | K14: 51.4 | N14: Broken Garlic | O14: =SUMIF(B6:B126,"Broken Garlic",C6:C126) -> 18.14
A15: 45902 | B15: Ginger | C15: 56.7 | E15: 45904 | F15: Ginger | G15: 50.57 | I15: 45905 | J15: Garlic Peeled | K15: 9 | N15: OS - Garlic Peeled | O15: =SUMIF(B6:B126,"OS - Garlic Peeled",C6:C126) -> 12 | P15: =O15 -> 12
A16: 45903 | B16: Ginger | C16: 56.76 | E16: 45905 | F16: Garlic | G16: 30.17 | I16: 45906 | J16: Garlic Peeled | K16: 11 | N16: OS - Ginger Peeled | O16: =SUMIF(B6:B126,"OS - Ginger Peeled",C6:C126) -> 0
A17: 45903 | B17: Ginger | C17: 56.95 | E17: 45905 | F17: Ginger | G17: 26.48 | I17: 45906 | J17: Ginger Peeled | K17: 0.5 | N17: OS - Ginger Garlic Paste | O17: =SUMIF(B6:B126,"OS - Ginger Garlic Paste",C6:C126) -> 100
A18: 45903 | B18: Garlic | C18: 125 | E18: 45906 | F18: Garlic | G18: 29.98 | I18: 45906 | J18: Ginger Peeled | K18: 11 | N18: Ginger Paste | O18: =SUMIF(B6:B126,"OS - Ginger Paste",C6:C126) -> 0
A19: 45905 | B19: Ginger | C19: 56.56 | E19: 45906 | F19: Ginger | G19: 25.19 | I19: 45906 | J19: Ginger Garlic Paste | K19: 92.5 | N19: Garlic Paste | O19: =SUMIF(B6:B126,"OS - Garlic Paste",C6:C126) -> 0
A20: 45908 | B20: Ginger | C20: 56.96 | E20: 45906 | F20: Garlic | G20: 29.95 | I20: 45908 | J20: Ginger Garlic Paste | K20: 43.2
A21: 45908 | B21: Garlic | C21: 30 | E21: 45908 | F21: Ginger | G21: 24.8 | I21: 45909 | J21: Garlic Peeled | K21: 4 | N21: Pre-Production | O21: Total(Kgs) | P21: Total(Kgs)
A22: 45908 | B22: Garlic | C22: 30 | E22: 45908 | F22: Garlic | G22: 20 | I22: 45910 | J22: Ginger Garlic Paste | K22: 58.42 | N22: Ginger | O22: =SUMIF(F6:F125,"Ginger",G6:G125) -> 648.42 | P22: =O22 -> 648.42
A23: 45908 | B23: Garlic | C23: 30 | E23: 45910 | F23: Garlic | G23: 30.1 | I23: 45911 | J23: Ginger Garlic Paste | K23: 84.6 | N23: Garlic | O23: =SUMIF(F6:F127,"Garlic",G6:G127) -> 925.76 | P23: =SUM(O23:O24) -> 981.76
A24: 45908 | B24: Garlic | C24: 30 | E24: 45910 | F24: Garlic | G24: 30.12 | I24: 45912 | J24: Ginger Garlic Paste | K24: 41 | N24: Broken Garlic | O24: =SUMIF(F6:F127,"Broken Garlic",G6:G127) -> 56
A25: 45908 | B25: Garlic | C25: 20 | E25: 45910 | F25: Garlic | G25: 30.1 | I25: 45912 | J25: Garlic Peeled | K25: 18
A26: 45908 | B26: Broken Garlic | C26: 6 | E26: 45910 | F26: Ginger | G26: 25.39 | I26: 45913 | J26: Ginger Garlic Paste | K26: 83
A27: 45909 | B27: Broken Garlic | C27: 4.54 | E27: 45911 | F27: Ginger | G27: 46.8 | I27: 45915 | J27: Ginger Garlic Paste | K27: 67.14 | N27: Post-Production | O27: Total(Kgs) | P27: Total Inclu. OS(Kgs)
A28: 45911 | B28: Ginger | C28: 56.97 | E28: 45911 | F28: Garlic | G28: 30 | I28: 45916 | J28: Garlic Peeled | K28: 17 | N28: Ginger Peeled | O28: =SUMIF(J6:J125,"Ginger Peeled",K6:K125) -> 11.5 | P28: =SUM(O28,O16) -> 11.5
A29: 45911 | B29: Garlic | C29: 39 | E29: 45912 | F29: Ginger | G29: 6.4 | I29: 45917 | J29: Ginger Garlic Paste | K29: 87.92 | N29: Garlic Peeled | O29: =SUMIF(J6:J125,"Garlic Peeled",K6:K125) -> 97 | P29: =SUM(O29,O15) -> 109
A30: 45911 | B30: Garlic | C30: 39.16 | E30: 45913 | F30: Garlic | G30: 39 | I30: 45919 | J30: Ginger Garlic Paste | K30: 81.31 | N30: Ginger Garlic Paste | O30: =SUMIF(J6:J125,"Ginger Garlic Paste",K6:K125) -> 1498.89 | P30: =SUM(O30,O17) -> 1598.89
A31: 45911 | B31: Garlic | C31: 38.55 | E31: 45913 | F31: Ginger | G31: 27.6 | I31: 45920 | J31: Ginger Garlic Paste | K31: 41.8 | N31: Ginger Paste | O31: =SUMIF(J6:J125,"Ginger Paste",K6:K125) -> 21 | P31: =SUM(O31,O18) -> 21
A32: 45911 | B32: Garlic | C32: 38.9 | E32: 45913 | F32: Ginger | G32: 9.22 | I32: 45921 | J32: Garlic Peeled | K32: 6 | N32: Garlic Paste | O32: =SUMIF(J6:J125,"Garlic Paste",K6:K125) -> 21 | P32: =SUM(O32,O19) -> 21
A33: 45911 | B33: Garlic | C33: 39 | E33: 45915 | F33: Garlic | G33: 38.7 | I33: 45921 | J33: Ginger Garlic Paste | K33: 93.5
A34: 45911 | B34: Garlic | C34: 39 | E34: 45915 | F34: Ginger | G34: 17.18 | I34: 45921 | J34: Garlic Peeled | K34: 6 | N34: Available Stock | O34: Total(Kgs)
A35: 45911 | B35: Garlic | C35: 38.92 | E35: 45915 | F35: Ginger | G35: 15.1 | I35: 45923 | J35: Ginger Garlic Paste | K35: 64 | N35: Gigner | O35: =P9-P22 -> 82.66
A36: 45911 | B36: Garlic | C36: 39 | E36: 45916 | F36: Garlic | G36: 38.97 | I36: 45924 | J36: Garlic Peeled | K36: 8 | N36: Garlic | O36: =Q11-P23 -> 351.23
A37: 45911 | B37: Garlic | C37: 38.79 | E37: 45917 | F37: Garlic | G37: 38.9 | I37: 45926 | J37: Garlic Peeled | K37: 6 | L37: .
A38: 45911 | B38: Garlic | C38: 39 | E38: 45917 | F38: Ginger | G38: 33.6 | I38: 45926 | J38: Ginger Garlic Paste | K38: 80
A39: 45911 | B39: Garlic | C39: 38.74 | E39: 45919 | F39: Garlic | G39: 38.53 | I39: 45927 | J39: Garlic Peeled | K39: 12
A40: 45911 | B40: Garlic | C40: 39 | E40: 45919 | F40: Ginger | G40: 12.31 | I40: 45928 | J40: Ginger Garlic Paste | K40: 51.5
A41: 45913 | B41: Ginger | C41: 56.6 | E41: 45919 | F41: Ginger | G41: 22.5 | I41: 45929 | J41: Ginger Garlic Paste | K41: 72
...

Sheet Oct 2025
E1: Nila Foods & Spices
A2: Daily Stock & Production | C2: 45931
A4: Stock-in | E4: Pre-Production | I4: Post-Production
A5: Date | B5: Material | C5: Weight(Kgs) | E5: Date | F5: Material | G5: Weight(Kgs) | I5: Date | J5: Material | K5: Weight(Kgs) | N5: OS - Opening Stock
A6: 45931 | B6: OS - Ginger | C6: 4.63 | E6: 45931 | F6: OS - Broken Garlic | G6: 29 | I6: 45931 | J6: Garlic Peeled | K6: 15
A7: 45931 | B7: OS - Garlic | C7: 298.03 | E7: 45932 | F7: Garlic | G7: 39.8 | I7: 45933 | J7: Garlic Peeled | K7: 12
A8: 45931 | B8: OS - Ginger Garlic Paste | C8: 111.22 | E8: 45933 | F8: Ginger | G8: 23.53 | I8: 45933 | J8: Ginger Garlic Paste | K8: 67.65 | N8: Overall Stock | O8: Total(Kgs) | P8: Total(kgs)
A9: 45931 | B9: OS - Garlic Peeled | E9: 45934 | F9: Garlic | G9: 29.61 | I9: 45934 | J9: Ginger Garlic Paste | K9: 57.2 | N9: OS - Ginger | O9: =SUMIF(B6:B125,"OS - Ginger",C6:C125) -> 4.63 | P9: =SUM(O9:O10) -> 441.88
A10: 45931 | B10: OS - Ginger Peeled | E10: 45934 | F10: Ginger | G10: 27.24 | I10: 45934 | J10: Garlic Peeled | K10: 1.5 | N10: Ginger | O10: =SUMIF(B6:B125,"Ginger",C6:C125) -> 437.25
A11: 45931 | B11: OS - Broken Garlic | C11: 42.39 | E11: 45936 | F11: Garlic | G11: 39.8 | I11: 45936 | J11: Ginger Garlic Paste | K11: 57.2 | N11: OS - Garlic | O11: =SUMIF(B6:B125,"OS - Garlic",C6:C125) -> 298.03 | P11: =SUM(O11:O12) -> 972.88 | Q11: =SUM(P11:P14) -> 1015.27
A12: 45931 | B12: Broken Garlic | E12: 45936 | F12: Ginger | G12: 19.87 | I12: 45938 | J12: Ginger Garlic Paste | K12: 55.8 | N12: Garlic Purchase | O12: =SUMIF(B6:B125,"Garlic",C6:C125) -> 674.85
A13: 45931 | B13: OS - Ginger Paste | E13: 45938 | F13: Garlic | G13: 29.6 | I13: 45939 | J13: Garlic Peeled | K13: 15 | N13: OS - Broken Garlic | O13: =SUMIF(B6:B125,"OS - Broken Garlic",C6:C125) -> 42.39 | P13: =SUM(O13:O14) -> 42.39
A14: 45931 | B14: OS - Garlic Paste | E14: 45938 | F14: Garlic | G14: 39.7 | I14: 45940 | J14: Ginger Garlic Paste | K14: 92.4 | N14: Broken Garlic | O14: =SUMIF(B6:B125,"Broken Garlic",C6:C125) -> 0
A15: 45931 | B15: Ginger | C15: 56.35 | E15: 45938 | F15: Ginger | G15: 31.9 | I15: 45941 | J15: Garlic Peeled | K15: 12 | N15: OS - Garlic Peeled | O15: =SUMIF(B6:B125,"OS - Garlic Peeled",C6:C125) -> 0 | P15: =O15 -> 0
A16: 45936 | B16: Ginger | C16: 56.7 | E16: 45939 | F16: Garlic | G16: 39.68 | I16: 45943 | J16: Ginger Garlic Paste | K16: 71 | N16: OS - Ginger Peeled | O16: =SUMIF(B6:B125,"OS - Ginger Peeled",C6:C125) -> 0
A17: 45937 | B17: Ginger | C17: 56.63 | E17: 45940 | F17: Ginger | G17: 36.14 | I17: 45945 | J17: Garlic Peeled | K17: 17 | N17: OS - Ginger Garlic Paste | O17: =SUMIF(B6:B125,"OS - Ginger Garlic Paste",C6:C125) -> 111.22
A18: 45941 | B18: Garlic | C18: 39.3 | E18: 45941 | F18: Garlic | G18: 39.47 | I18: 45947 | J18: Ginger Garlic Paste | K18: 89.8 | N18: Ginger Paste | O18: =SUMIF(B6:B125,"OS - Ginger Paste",C6:C125) -> 0
A19: 45941 | B19: Garlic | C19: 39.25 | E19: 45943 | F19: Ginger | G19: 22.4 | I19: 45947 | J19: Garlic Peeled | K19: 6 | N19: Garlic Paste | O19: =SUMIF(B6:B125,"OS - Garlic Paste",C6:C125) -> 0
A20: 45941 | B20: Garlic | C20: 39.38 | E20: 45945 | F20: Garlic | G20: 39.2 | I20: 45949 | J20: Ginger Garlic Paste | K20: 100.5
A21: 45941 | B21: Garlic | C21: 39 | E21: 45945 | F21: Garlic | G21: 39.6 | I21: 45951 | J21: Garlic Peeled | K21: 8 | N21: Pre-Production | O21: Total(Kgs) | P21: Total(Kgs)
A22: 45941 | B22: Garlic | C22: 39.14 | E22: 45947 | F22: Ginger | G22: 38.17 | I22: 45952 | J22: Ginger Garlic Paste | K22: 49 | N22: Ginger | O22: =SUMIF(F6:F125,"Ginger",G6:G125) -> 403.45 | P22: =O22 -> 403.45
A23: 45941 | B23: Garlic | C23: 39.18 | E23: 45948 | F23: Garlic | G23: 39.33 | I23: 45953 | J23: Ginger Paste | K23: 15 | N23: Garlic | O23: =SUMIF(F6:F125,"Garlic",G6:G125) -> 651.18 | P23: =SUM(O23:O24) -> 651.18
A24: 45941 | B24: Garlic | C24: 39.23 | E24: 45949 | F24: Ginger | G24: 40 | I24: 45953 | J24: Garlic Paste | K24: 15 | N24: Broken Garlic | O24: =SUMIF(F6:F125,"Broken Garlic",G6:G125) -> 0
A25: 45944 | B25: Ginger | C25: 40.13 | E25: 45951 | F25: Garlic | G25: 38.99 | I25: 45953 | J25: Ginger Garlic Paste | K25: 7.84
A26: 45948 | B26: Ginger | C26: 50 | E26: 45952 | F26: Ginger | G26: 17.41 | I26: 45953 | J26: Garlic Peeled | K26: 7
A27: 45953 | B27: Ginger | C27: 59.64 | E27: 45953 | F27: Garlic | G27: 39.05 | I27: 45954 | J27: Garlic Peeled | K27: 25.5 | N27: Post-Production | O27: Total(Kgs) | P27: Total Inclu. OS(Kgs)
A28: 45957 | B28: Garlic | C28: 39.97 | E28: 45953 | F28: Ginger | G28: 14.27 | I28: 45955 | J28: Ginger Garlic Paste | K28: 78 | N28: Ginger Peeled | O28: =SUMIF(J6:J125,"Ginger Peeled",K6:K125) -> 0 | P28: =SUM(O28,O16) -> 0
A29: 45957 | B29: Garlic | C29: 39.8 | E29: 45953 | F29: Ginger | G29: 8.83 | I29: 45956 | J29: Ginger Garlic Paste | K29: 22.22 | N29: Garlic Peeled | O29: =SUMIF(J6:J125,"Garlic Peeled",K6:K125) -> 141.5 | P29: =SUM(O29,O15) -> 141.5
A30: 45957 | B30: Garlic | C30: 39.84 | E30: 45955 | F30: Garlic | G30: 39 | I30: 45957 | J30: Ginger Garlic Paste | K30: 58.1 | N30: Ginger Garlic Paste | O30: =SUMIF(J6:J125,"Ginger Garlic Paste",K6:K125) -> 926.14 | P30: =SUM(O30,O17) -> 1037.36
A31: 45957 | B31: Garlic | C31: 39.89 | E31: 45955 | F31: Ginger | G31: 33.48 | I31: 45957 | J31: Garlic Peeled | K31: 8 | N31: Ginger Paste | O31: =SUMIF(J6:J125,"Ginger Paste",K6:K125) -> 15 | P31: =SUM(O31,O18) -> 15
A32: 45957 | B32: Garlic | C32: 39.94 | E32: 45956 | F32: Ginger | G32: 19.8 | I32: 45958 | J32: Garlic Peeled | K32: 8.5 | N32: Garlic Paste | O32: =SUMIF(J6:J125,"Garlic Paste",K6:K125) -> 15 | P32: =SUM(O32,O19) -> 15
A33: 45957 | B33: Garlic | C33: 39.67 | E33: 45957 | F33: Ginger | G33: 15 | I33: 45958 | J33: Ginger Garlic Paste | K33: 58.5
A34: 45957 | B34: Garlic | C34: 39.89 | E34: 45957 | F34: Garlic | G34: 39 | I34: 45960 | J34: Garlic Peeled | K34: 6 | N34: Available Stock | O34: Total(Kgs)
A35: 45957 | B35: Garlic | C35: 41.53 | E35: 45958 | F35: Garlic | G35: 39.87 | I35: 45961 | J35: Ginger Garlic Paste | K35: 60.93 | N35: Gigner | O35: =P9-P22 -> 38.43
A36: 45957 | B36: Garlic | C36: 39.87 | E36: 45958 | F36: Ginger | G36: 29.19 | N36: Garlic | O36: =Q11-P23 -> 364.09
A37: 45957 | B37: Garlic | C37: 39.97 | E37: 45959 | F37: Garlic | G37: 39.72 | L37: .
A38: 45958 | B38: Ginger | C38: 58.8 | E38: 45960 | F38: Garlic | G38: 39.76
A39: 45941 | B39: Ginger | C39: 25 | E39: 45961 | F39: Ginger | G39: 26.22
A40: 45956 | B40: Ginger | C40: 34
B126: . | F126: . | J126: .

Sheet Nov 2025
E1: Nila Foods & Spices
A2: Daily Stock & Production | C2: 45962
A4: Stock-in | E4: Pre-Production | I4: Post-Production
A5: Date | B5: Material | C5: Weight(Kgs) | E5: Date | F5: Material | G5: Weight(Kgs) | I5: Date | J5: Material | K5: Weight(Kgs) | N5: OS - Opening Stock
A6: 45962 | B6: OS - Ginger | E6: 45962 | F6: Garlic | G6: 38.79 | I6: 45962 | J6: Garlic Peeled | K6: 6
A7: 45962 | B7: OS - Garlic | C7: 278.17 | E7: 45962 | F7: Ginger | G7: 25.22 | I7: 45962 | J7: Ginger Garlic Paste | K7: 59.53
A8: 45962 | B8: OS - Ginger Garlic Paste | C8: 60.93 | E8: 45964 | F8: Garlic | G8: 38.12 | I8: 45964 | J8: Ginger Garlic Paste | K8: 58.15 | N8: Overall Stock | O8: Total(Kgs) | P8: Total(kgs)
A9: 45962 | B9: OS - Garlic Peeled | C9: 17.98 | E9: 45964 | F9: Ginger | G9: 28.96 | I9: 45965 | J9: Garlic Peeled | K9: 6.5 | N9: OS - Ginger | O9: =SUMIF(B6:B125,"OS - Ginger",C6:C125) -> 0 | P9: =SUM(O9:O10) -> 544.06
A10: 45962 | B10: OS - Ginger Peeled | C10: 0.15 | E10: 45965 | F10: Garlic | G10: 39.67 | I10: 45965 | J10: Ginger Garlic Paste | K10: 73.7 | N10: Ginger | O10: =SUMIF(B6:B125,"Ginger",C6:C125) -> 544.06
A11: 45962 | B11: OS - Broken Garlic | C11: 38.12 | E11: 45965 | F11: Ginger | G11: 28.6 | I11: 45967 | J11: Ginger Garlic Paste | K11: 68.88 | N11: OS - Garlic | O11: =SUMIF(B6:B125,"OS - Garlic",C6:C125) -> 278.17 | P11: =SUM(O11:O12) -> 1061.11 | Q11: =SUM(P11:P14) -> 1099.23
A12: 45962 | B12: Broken Garlic | E12: 45965 | F12: Garlic | G12: 39.7 | I12: 45968 | J12: Garlic Peeled | K12: 21 | N12: Garlic Purchase | O12: =SUMIF(B6:B125,"Garlic",C6:C125) -> 782.94
A13: 45962 | B13: OS - Ginger Paste | E13: 45967 | F13: Ginger | G13: 23.3 | I13: 45969 | J13: Garlic Peeled | K13: 5 | N13: OS - Broken Garlic | O13: =SUMIF(B6:B125,"OS - Broken Garlic",C6:C125) -> 38.12 | P13: =SUM(O13:O14) -> 38.12
A14: 45962 | B14: OS - Garlic Paste | E14: 45967 | F14: Ginger | G14: 7.3 | I14: 45969 | J14: Ginger Garlic Paste | K14: 58.79 | N14: Broken Garlic | O14: =SUMIF(B6:B125,"Broken Garlic",C6:C125) -> 0
A15: 45962 | B15: Ginger | C15: 56.91 | E15: 45968 | F15: Garlic | G15: 39.67 | I15: 45971 | J15: Ginger Garlic Paste | K15: 61 | N15: OS - Garlic Peeled | O15: =SUMIF(B6:B125,"OS - Garlic Peeled",C6:C125) -> 17.98 | P15: =O15 -> 17.98
A16: 45965 | B16: Ginger | C16: 30 | E16: 45969 | F16: Garlic | G16: 39.78 | I16: 45971 | J16: Garlic Peeled | K16: 6 | N16: OS - Ginger Peeled | O16: =SUMIF(B6:B125,"OS - Ginger Peeled",C6:C125) -> 0.15
A17: 45966 | B17: Ginger | C17: 56.96 | E17: 45969 | F17: Ginger | G17: 22.64 | I17: 45973 | J17: Garlic Peeled | K17: 7 | N17: OS - Ginger Garlic Paste | O17: =SUMIF(B6:B125,"OS - Ginger Garlic Paste",C6:C125) -> 60.93
A18: 45971 | B18: Ginger | C18: 56.99 | E18: 45971 | F18: Ginger | G18: 9.21 | I18: 45973 | J18: Ginger Garlic Paste | K18: 54.47 | N18: Ginger Paste | O18: =SUMIF(B6:B125,"OS - Ginger Paste",C6:C125) -> 0
A19: 45973 | B19: Garlic | C19: 39.38 | E19: 45971 | F19: Ginger | G19: 26 | I19: 45975 | J19: Garlic Peeled | K19: 5 | N19: Garlic Paste | O19: =SUMIF(B6:B125,"OS - Garlic Paste",C6:C125) -> 0
A20: 45973 | B20: Garlic | C20: 39.6 | E20: 45972 | F20: Garlic | G20: 39.5 | I20: 45975 | J20: Ginger Garlic Paste | K20: 60
A21: 45973 | B21: Garlic | C21: 39.33 | E21: 45973 | F21: Ginger | G21: 18.33 | I21: 45976 | J21: Ginger Garlic Paste | K21: 70.92 | N21: Pre-Production | O21: Total(Kgs) | P21: Total(Kgs)
A22: 45973 | B22: Garlic | C22: 39.53 | E22: 45974 | F22: Garlic | G22: 39.42 | I22: 45976 | J22: Garlic Peeled | K22: 5 | N22: Ginger | O22: =SUMIF(F6:F125,"Ginger",G6:G125) -> 464.72 | P22: =O22 -> 464.72 | R22: =SUM(P22:P24) -> 1211.61
A23: 45973 | B23: Garlic | C23: 39.69 | E23: 45975 | F23: Ginger | G23: 24.75 | I23: 45978 | J23: Garlic Peeled | K23: 5 | N23: Garlic | O23: =SUMIF(F6:F125,"Garlic",G6:G125) -> 746.89 | P23: =SUM(O23:O24) -> 746.89
A24: 45973 | B24: Garlic | C24: 39.27 | E24: 45975 | F24: Garlic | G24: 39.35 | I24: 45979 | J24: Ginger Garlic Paste | K24: 56 | N24: Broken Garlic | O24: =SUMIF(F6:F125,"Broken Garlic",G6:G125) -> 0
A25: 45973 | B25: Garlic | C25: 39.55 | E25: 45976 | F25: Ginger | G25: 30.79 | I25: 45980 | J25: Ginger Garlic Paste | K25: 69
A26: 45973 | B26: Garlic | C26: 39.4 | E26: 45978 | F26: Garlic | G26: 39 | I26: 45982 | J26: Garlic Peeled | K26: 17
A27: 45973 | B27: Garlic | C27: 39.47 | E27: 45979 | F27: Ginger | G27: 25.38 | I27: 45983 | J27: Ginger Garlic Paste | K27: 121 | N27: Post-Production | O27: Total(Kgs) | P27: Total Inclu. OS(Kgs)
A28: 45973 | B28: Garlic | C28: 39.42 | E28: 45979 | F28: Garlic | G28: 39.48 | I28: 45984 | J28: Ginger Garlic Paste | K28: 54 | N28: Ginger Peeled | O28: =SUMIF(J6:J125,"Ginger Peeled",K6:K125) -> 0 | P28: =SUM(O28,O16) -> 0.15 | R28: =SUM(P28:P32) -> 1296.82
A29: 45974 | B29: Ginger | C29: 56.78 | E29: 45980 | F29: Ginger | G29: 28.62 | I29: 45985 | J29: Ginger Garlic Paste | K29: 69.39 | N29: Garlic Peeled | O29: =SUMIF(J6:J125,"Garlic Peeled",K6:K125) -> 91.5 | P29: =SUM(O29,O15) -> 109.48
A30: 45979 | B30: Ginger | C30: 56.79 | E30: 45982 | F30: Garlic | G30: 39.47 | I30: 45986 | J30: Garlic Peeled | K30: 8 | N30: Ginger Garlic Paste | O30: =SUMIF(J6:J125,"Ginger Garlic Paste",K6:K125) -> 1126.26 | P30: =SUM(O30,O17) -> 1187.19
A31: 45983 | B31: Ginger | C31: 115.79 | E31: 45983 | F31: Garlic | G31: 39.45 | I31: 45987 | J31: Ginger Garlic Paste | K31: 69.43 | N31: Ginger Paste | O31: =SUMIF(J6:J125,"Ginger Paste",K6:K125) -> 0 | P31: =SUM(O31,O18) -> 0
A32: 45986 | B32: Ginger | C32: 113.84 | E32: 45983 | F32: Garlic | G32: 39.37 | I32: 45989 | J32: Ginger Garlic Paste | K32: 63 | N32: Garlic Paste | O32: =SUMIF(J6:J125,"Garlic Paste",K6:K125) -> 0 | P32: =SUM(O32,O19) -> 0
A33: 45988 | B33: Garlic | C33: 38.94 | E33: 45983 | F33: Ginger | G33: 50.38 | I33: 45990 | J33: Ginger Garlic Paste | K33: 59
A34: 45988 | B34: Garlic | C34: 34.7 | E34: 45984 | F34: Garlic | G34: 39.22 | N34: Available Stock | O34: Total(Kgs)
A35: 45988 | B35: Garlic | C35: 39.59 | E35: 45984 | F35: Ginger | G35: 23.6 | N35: Gigner | O35: =P9-P22 -> 79.34
A36: 45988 | B36: Garlic | C36: 38.2 | E36: 45985 | F36: Ginger | G36: 18.86 | N36: Garlic | O36: =Q11-P23 -> 352.34
A37: 45988 | B37: Garlic | C37: 39.98 | E37: 45986 | F37: Garlic | G37: 39.15 | L37: .
A38: 45988 | B38: Garlic | C38: 39.3 | E38: 45987 | F38: Ginger | G38: 36.7
A39: 45988 | B39: Garlic | C39: 39.2 | E39: 45988 | F39: Garlic | G39: 39
A40: 45988 | B40: Garlic | C40: 39.5 | E40: 45989 | F40: Garlic | G40: 39.5
A41: 45988 | B41: Garlic | C41: 39.52 | E41: 45989 | F41: Garlic | G41: 39.25
...

Sheet Dec 2025 
E1: Nila Foods & Spices
A2: Daily Stock & Production | C2: 45992
A4: Stock-in | E4: Pre-Production | I4: Post-Production
A5: Date | B5: Material | C5: Weight(Kgs) | E5: Date | F5: Material | G5: Weight(Kgs) | I5: Date | J5: Material | K5: Weight(Kgs) | N5: OS - Opening Stock
A6: 45992 | B6: OS - Ginger(Raw) | C6: 50 | E6: 45992 | F6: OS - Broken Garlic | G6: 46.9 | I6: 45992 | J6: Garlic Peeled | K6: 7
A7: 45992 | B7: OS - Garlic(Raw) | C7: 308.61 | E7: 45992 | F7: Ginger | G7: 40.8 | I7: 45992 | J7: Ginger Garlic Paste | K7: 69.4
A8: 45992 | B8: OS - Ginger Garlic Paste(Processed) | C8: 52 | E8: 45993 | F8: Garlic | G8: 38.6 | I8: 45993 | J8: Garlic Peeled | K8: 7 | N8: Overall Stock | O8: Total(Kgs) | P8: Total(kgs)
A9: 45992 | B9: OS - Garlic Peeled(Processed) | C9: 6.2 | E9: 45993 | F9: Garlic | G9: 34.7 | I9: 45994 | J9: Ginger Garlic Paste | K9: 95 | N9: OS - Ginger | O9: =SUMIF(B6:B128,"OS - Ginger(Raw)",C6:C128) -> 55 | P9: =SUM(O9:O10) -> 745.68
A10: 45992 | B10: OS - Ginger Peeled(Processed) | C10: 1.5 | E10: 45993 | F10: Ginger | G10: 23.9 | I10: 45994 | J10: Garlic Peeled | K10: 8 | N10: Ginger | O10: =SUMIF(B6:B128,"Ginger",C6:C128) -> 690.68
A11: 45992 | B11: OS - Broken Garlic(Raw) | C11: 46.9 | E11: 45996 | F11: Garlic | G11: 38.85 | I11: 45997 | J11: Garlic Peeled | K11: 13 | N11: OS - Garlic | O11: =SUMIF(B6:B128,"OS - Garlic(Raw)",C6:C128) -> 308.61 | P11: =SUM(O11:O12) -> 1701.73 | Q11: =SUM(P11:P14) -> 1701.73
A12: 45992 | B12: Broken Garlic | E12: 45996 | F12: Garlic | G12: 39 | I12: 45997 | J12: Ginger Garlic Paste | K12: 125 | N12: Garlic Purchase | O12: =SUMIF(B6:B128,"Garlic",C6:C128) -> 1393.12
A13: 45992 | B13: OS - Ginger Paste(Processed) | E13: 45997 | F13: Ginger | G13: 33.96 | I13: 45998 | J13: Garlic Peeled | K13: 16 | N13: OS - Broken Garlic | O13: =SUMIF(B6:B128,"OS - Broken Garlic",C6:C128) -> 0 | P13: =SUM(O13:O14) -> 0
